Workbook

Sheet DRE 2026
B2: Demonstrativos Financeiros - 2026 Consolidado | C2: JANEIRO | D2: FEVEREIRO | E2: MARÇO | F2: ABRIL | G2: MAIO | H2: JUNHO | I2: JULHO | J2: AGOSTO | K2: SETEMBRO | L2: OUTUBRO | M2: NOVEMBRO | N2: DEZEMBRO | P2: 1 SEM | Q2: 2 SEM | R2: 2025
B3: DRE (R$)
B4: Receita Operacional Bruta | C4: =SUM(C5:C15) -> 276257.97 | D4: =SUM(D5:D15) -> 302537.98 | E4: =SUM(E5:E15) -> 297990.92 | F4: =SUM(F5:F15) -> 235626.88 | G4: =SUM(G5:G15) -> 242586.46 | H4: =SUM(H5:H15) -> 283604.11 | I4: =IFERROR(__xludf.DUMMYFUNCTION("importrange(""1QxQzD8FYlG3qLn8OXtKW9gfO6pUDR-FCSW3X-_jPPGQ"",""'DRE 2026'!I4:N133"")"),305701.16) -> 305701.16 | J4: =IFERROR(__xludf.DUMMYFUNCTION("""COMPUTED_VALUE"""),414516.74) -> 414516.74 | K4: =IFERROR(__xludf.DUMMYFUNCTION("""COMPUTED_VALUE"""),0) -> 0 | L4: =IFERROR(__xludf.DUMMYFUNCTION("""COMPUTED_VALUE"""),0) -> 0 | M4: =IFERROR(__xludf.DUMMYFUNCTION("""COMPUTED_VALUE"""),0) -> 0 | N4: =IFERROR(__xludf.DUMMYFUNCTION("""COMPUTED_VALUE"""),0) -> 0 | P4: =C4+D4+E4+F4+G4+H4 -> 1638604.3 | Q4: =I4+J4+K4+L4+M4+N4 -> 720217.9 | R4: =Q4+P4 -> 2358822.2
B5: Receita com Taxa de Vendas Online - Formaturas | C5: 110204.65 | D5: 125561.86 | E5: 101436.85 | F5: 64504.04 | G5: 62018.63 | H5: 85436.05 | I5: =IFERROR(__xludf.DUMMYFUNCTION("""COMPUTED_VALUE"""),92571.47) -> 92571.47 | J5: =IFERROR(__xludf.DUMMYFUNCTION("""COMPUTED_VALUE"""),146550.37) -> 146550.37 | P5: =C5+D5+E5+F5+G5+H5 -> 549162.08 | Q5: =I5+J5+K5+L5+M5+N5 -> 239121.84 | R5: =Q5+P5 -> 788283.92
B6: Receita com Taxa de Parcelamento Online - Formaturas | C6: 80333.42 | D6: 81422.18 | E6: 72656.14 | F6: 39955.32 | G6: 42199.76 | H6: 57866.42 | I6: =IFERROR(__xludf.DUMMYFUNCTION("""COMPUTED_VALUE"""),66241.41) -> 66241.41 | J6: =IFERROR(__xludf.DUMMYFUNCTION("""COMPUTED_VALUE"""),100191.14) -> 100191.14 | P6: =C6+D6+E6+F6+G6+H6 -> 374433.24 | Q6: =I6+J6+K6+L6+M6+N6 -> 166432.55 | R6: =Q6+P6 -> 540865.79
B7: Receita com Taxa de Vendas Online - Eventos em Geral | C7: 63839.69 | D7: 62635.2 | E7: 88391.41 | F7: 92904.64 | G7: 101577.49 | H7: 93967.24 | I7: =IFERROR(__xludf.DUMMYFUNCTION("""COMPUTED_VALUE"""),103254.14) -> 103254.14 | J7: =IFERROR(__xludf.DUMMYFUNCTION("""COMPUTED_VALUE"""),121923.04) -> 121923.04 | P7: =C7+D7+E7+F7+G7+H7 -> 503315.67 | Q7: =I7+J7+K7+L7+M7+N7 -> 225177.18 | R7: =Q7+P7 -> 728492.85
B8: Receita com Taxa de Parcelamento Online - Eventos em Geral | C8: 13800.06 | D8: 21745.76 | E8: 25291.26 | F8: 27044.99 | G8: 22268.77 | H8: 29541.43 | I8: =IFERROR(__xludf.DUMMYFUNCTION("""COMPUTED_VALUE"""),28964.19) -> 28964.19 | J8: =IFERROR(__xludf.DUMMYFUNCTION("""COMPUTED_VALUE"""),31761.79) -> 31761.79 | P8: =C8+D8+E8+F8+G8+H8 -> 139692.27 | Q8: =I8+J8+K8+L8+M8+N8 -> 60725.98 | R8: =Q8+P8 -> 200418.25
B9: Receita com Taxa de Cartão | C9: 2006 | D9: 3700 | E9: 2166 | F9: 2562 | G9: 4442 | H9: 2643 | I9: =IFERROR(__xludf.DUMMYFUNCTION("""COMPUTED_VALUE"""),878) -> 878 | J9: =IFERROR(__xludf.DUMMYFUNCTION("""COMPUTED_VALUE"""),2504) -> 2504 | P9: =C9+D9+E9+F9+G9+H9 -> 17519 | Q9: =I9+J9+K9+L9+M9+N9 -> 3382 | R9: =Q9+P9 -> 20901
B10: Receita com Taxa de Administração | C10: 1098.25 | D10: 1452 | E10: 1823.7 | F10: 1539.7 | G10: 1894.79 | H10: 3814.95 | I10: =IFERROR(__xludf.DUMMYFUNCTION("""COMPUTED_VALUE"""),1167.6) -> 1167.6 | J10: =IFERROR(__xludf.DUMMYFUNCTION("""COMPUTED_VALUE"""),2062.4) -> 2062.4 | P10: =C10+D10+E10+F10+G10+H10 -> 11623.39 | Q10: =I10+J10+K10+L10+M10+N10 -> 3230 | R10: =Q10+P10 -> 14853.39
B11: Receita com Taxa de Processamento | C11: 4875.9 | D11: 5461.52 | E11: 5920.56 | F11: 6831.19 | G11: 7684 | H11: 10060.02 | I11: =IFERROR(__xludf.DUMMYFUNCTION("""COMPUTED_VALUE"""),11539.62) -> 11539.62 | J11: =IFERROR(__xludf.DUMMYFUNCTION("""COMPUTED_VALUE"""),9314) -> 9314 | P11: =C11+D11+E11+F11+G11+H11 -> 40833.19 | Q11: =I11+J11+K11+L11+M11+N11 -> 20853.62 | R11: =Q11+P11 -> 61686.81
B12: Receita com Taxas de Antecipação | C12: 0 | D12: 319.46 | E12: 0 | F12: 0 | G12: 327.02 | H12: 0 | I12: =IFERROR(__xludf.DUMMYFUNCTION("""COMPUTED_VALUE"""),949.73) -> 949.73 | J12: =IFERROR(__xludf.DUMMYFUNCTION("""COMPUTED_VALUE"""),0) -> 0 | P12: =C12+D12+E12+F12+G12+H12 -> 646.48 | Q12: =I12+J12+K12+L12+M12+N12 -> 949.73 | R12: =Q12+P12 -> 1596.21
B13: Receita com Locação de Equipamentos | C13: 0 | D13: 0 | E13: 0 | F13: 0 | G13: 0 | H13: 0 | I13: =IFERROR(__xludf.DUMMYFUNCTION("""COMPUTED_VALUE"""),0) -> 0 | J13: =IFERROR(__xludf.DUMMYFUNCTION("""COMPUTED_VALUE"""),0) -> 0 | P13: =C13+D13+E13+F13+G13+H13 -> 0 | Q13: =I13+J13+K13+L13+M13+N13 -> 0 | R13: =Q13+P13 -> 0
B14: Receita com Licença de Uso | C14: 0 | D14: 0 | E14: 0 | F14: 0 | G14: 0 | H14: 0 | I14: =IFERROR(__xludf.DUMMYFUNCTION("""COMPUTED_VALUE"""),0) -> 0 | J14: =IFERROR(__xludf.DUMMYFUNCTION("""COMPUTED_VALUE"""),0) -> 0 | P14: =C14+D14+E14+F14+G14+H14 -> 0 | Q14: =I14+J14+K14+L14+M14+N14 -> 0 | R14: =Q14+P14 -> 0
B15: Receita com Vendas de QR Codes | C15: 100 | D15: 240 | E15: 305 | F15: 285 | G15: 174 | H15: 275 | I15: =IFERROR(__xludf.DUMMYFUNCTION("""COMPUTED_VALUE"""),135) -> 135 | J15: =IFERROR(__xludf.DUMMYFUNCTION("""COMPUTED_VALUE"""),210) -> 210 | P15: =C15+D15+E15+F15+G15+H15 -> 1379 | Q15: =I15+J15+K15+L15+M15+N15 -> 345 | R15: =Q15+P15 -> 1724
B16: Deduções de Receita | C16: =SUM(C17:C19) -> -40017.8 | D16: =SUM(D17:D19) -> -39398.19 | E16: =SUM(E17:E19) -> -27355.42 | F16: =SUM(F17:F19) -> -36236.73 | G16: =SUM(G17:G19) -> -28528.1 | H16: =SUM(H17:H19) -> -39028.04 | I16: =IFERROR(__xludf.DUMMYFUNCTION("""COMPUTED_VALUE"""),-43587.67) -> -43587.67 | J16: =IFERROR(__xludf.DUMMYFUNCTION("""COMPUTED_VALUE"""),-28063.11) -> -28063.11 | K16: =IFERROR(__xludf.DUMMYFUNCTION("""COMPUTED_VALUE"""),0) -> 0 | L16: =IFERROR(__xludf.DUMMYFUNCTION("""COMPUTED_VALUE"""),0) -> 0 | M16: =IFERROR(__xludf.DUMMYFUNCTION("""COMPUTED_VALUE"""),0) -> 0 | N16: =IFERROR(__xludf.DUMMYFUNCTION("""COMPUTED_VALUE"""),0) -> 0 | P16: =C16+D16+E16+F16+G16+H16 -> -210564.28 | Q16: =I16+J16+K16+L16+M16+N16 -> -71650.78 | R16: =Q16+P16 -> -282215.06
B17: Devoluções de Compra de Serviços (Chargeback) | C17: -3999.96 | D17: -6683.42 | E17: -3125.48 | F17: -6677 | G17: -4985.44 | H17: -5484.14 | I17: =IFERROR(__xludf.DUMMYFUNCTION("""COMPUTED_VALUE"""),-14612.15) -> -14612.15 | J17: =IFERROR(__xludf.DUMMYFUNCTION("""COMPUTED_VALUE"""),-19866.11) -> -19866.11 | P17: =C17+D17+E17+F17+G17+H17 -> -30955.44 | Q17: =I17+J17+K17+L17+M17+N17 -> -34478.26 | R17: =Q17+P17 -> -65433.7
B18: Devoluções de Compra (Estornos) | C18: -315 | D18: 0 | E18: 0 | F18: 0 | G18: -368.6 | H18: 0 | I18: =IFERROR(__xludf.DUMMYFUNCTION("""COMPUTED_VALUE"""),-380) -> -380 | J18: =IFERROR(__xludf.DUMMYFUNCTION("""COMPUTED_VALUE"""),0) -> 0 | P18: =C18+D18+E18+F18+G18+H18 -> -683.6 | Q18: =I18+J18+K18+L18+M18+N18 -> -380 | R18: =Q18+P18 -> -1063.6
B19: Simples Nacional (DAS) | C19: -35702.84 | D19: -32714.77 | E19: -24229.94 | F19: -29559.73 | G19: -23174.06 | H19: -33543.9 | I19: =IFERROR(__xludf.DUMMYFUNCTION("""COMPUTED_VALUE"""),-28595.52) -> -28595.52 | J19: =IFERROR(__xludf.DUMMYFUNCTION("""COMPUTED_VALUE"""),-8197) -> -8197 | P19: =C19+D19+E19+F19+G19+H19 -> -178925.24 | Q19: =I19+J19+K19+L19+M19+N19 -> -36792.52 | R19: =Q19+P19 -> -215717.76
B20: Receita Operacional Liquida | C20: =C16+C4 -> 236240.17 | D20: =D16+D4 -> 263139.79 | E20: =E16+E4 -> 270635.5 | F20: =F16+F4 -> 199390.15 | G20: =G16+G4 -> 214058.36 | H20: =H16+H4 -> 244576.07 | I20: =IFERROR(__xludf.DUMMYFUNCTION("""COMPUTED_VALUE"""),262113.49) -> 262113.49 | J20: =IFERROR(__xludf.DUMMYFUNCTION("""COMPUTED_VALUE"""),386453.63) -> 386453.63 | K20: =IFERROR(__xludf.DUMMYFUNCTION("""COMPUTED_VALUE"""),0) -> 0 | L20: =IFERROR(__xludf.DUMMYFUNCTION("""COMPUTED_VALUE"""),0) -> 0 | M20: =IFERROR(__xludf.DUMMYFUNCTION("""COMPUTED_VALUE"""),0) -> 0 | N20: =IFERROR(__xludf.DUMMYFUNCTION("""COMPUTED_VALUE"""),0) -> 0 | P20: =C20+D20+E20+F20+G20+H20 -> 1428040 | Q20: =I20+J20+K20+L20+M20+N20 -> 648567.12 | R20: =Q20+P20 -> 2076607.2
B21: Custos com os Serviços Prestados | C21: =SUM(C22:C26) -> -65505.12 | D21: =SUM(D22:D26) -> -73305.13 | E21: =SUM(E22:E26) -> -69757.14 | F21: =SUM(F22:F26) -> -56260.37 | G21: =SUM(G22:G26) -> -54369.77 | H21: =SUM(H22:H26) -> -73768.21 | I21: =IFERROR(__xludf.DUMMYFUNCTION("""COMPUTED_VALUE"""),-76154.4899999999) -> -76154.49 | J21: =IFERROR(__xludf.DUMMYFUNCTION("""COMPUTED_VALUE"""),-110740.75) -> -110740.75 | K21: =IFERROR(__xludf.DUMMYFUNCTION("""COMPUTED_VALUE"""),0) -> 0 | L21: =IFERROR(__xludf.DUMMYFUNCTION("""COMPUTED_VALUE"""),0) -> 0 | M21: =IFERROR(__xludf.DUMMYFUNCTION("""COMPUTED_VALUE"""),0) -> 0 | N21: =IFERROR(__xludf.DUMMYFUNCTION("""COMPUTED_VALUE"""),0) -> 0 | P21: =C21+D21+E21+F21+G21+H21 -> -392965.74 | Q21: =I21+J21+K21+L21+M21+N21 -> -186895.24 | R21: =Q21+P21 -> -579860.98
B22: Compras de Materia Prima | C22: 0 | D22: 0 | E22: 0 | F22: 0 | G22: 0 | H22: -3925 | I22: =IFERROR(__xludf.DUMMYFUNCTION("""COMPUTED_VALUE"""),0) -> 0 | J22: =IFERROR(__xludf.DUMMYFUNCTION("""COMPUTED_VALUE"""),-4207.6) -> -4207.6 | P22: =C22+D22+E22+F22+G22+H22 -> -3925 | Q22: =I22+J22+K22+L22+M22+N22 -> -4207.6 | R22: =Q22+P22 -> -8132.6
B23: Custo com Gateway de Pagamento | C23: -43699.12 | D23: -50149.13 | E23: -45278.14 | F23: -32563.37 | G23: -32399.77 | H23: -46697.21 | I23: =IFERROR(__xludf.DUMMYFUNCTION("""COMPUTED_VALUE"""),-50637.49) -> -50637.49 | J23: =IFERROR(__xludf.DUMMYFUNCTION("""COMPUTED_VALUE"""),-77538.64) -> -77538.64 | P23: =C23+D23+E23+F23+G23+H23 -> -250786.74 | Q23: =I23+J23+K23+L23+M23+N23 -> -128176.13 | R23: =Q23+P23 -> -378962.87
B24: Serviço de Mão de Obra Eventos / Suporte | C24: -2300 | D24: -2150 | E24: -2600 | F24: -4800 | G24: -1800 | H24: -1800 | I24: =IFERROR(__xludf.DUMMYFUNCTION("""COMPUTED_VALUE"""),-1750) -> -1750 | J24: =IFERROR(__xludf.DUMMYFUNCTION("""COMPUTED_VALUE"""),-3600) -> -3600 | P24: =C24+D24+E24+F24+G24+H24 -> -15450 | Q24: =I24+J24+K24+L24+M24+N24 -> -5350 | R24: =Q24+P24 -> -20800
B25: Royalties | C25: -19506 | D25: -21006 | E25: -21879 | F25: -18897 | G25: -20170 | H25: -21346 | I25: =IFERROR(__xludf.DUMMYFUNCTION("""COMPUTED_VALUE"""),-23767) -> -23767 | J25: =IFERROR(__xludf.DUMMYFUNCTION("""COMPUTED_VALUE"""),-25394.51) -> -25394.51 | P25: =C25+D25+E25+F25+G25+H25 -> -122804 | Q25: =I25+J25+K25+L25+M25+N25 -> -49161.51 | R25: =Q25+P25 -> -171965.51
B26: Compra de Serviços | C26: 0 | D26: 0 | E26: 0 | F26: 0 | G26: 0 | H26: 0 | I26: =IFERROR(__xludf.DUMMYFUNCTION("""COMPUTED_VALUE"""),0) -> 0 | J26: =IFERROR(__xludf.DUMMYFUNCTION("""COMPUTED_VALUE"""),0) -> 0 | P26: =C26+D26+E26+F26+G26+H26 -> 0 | Q26: =I26+J26+K26+L26+M26+N26 -> 0 | R26: =Q26+P26 -> 0
B27: Lucro Operacional Bruto | C27: =C20+C21 -> 170735.05 | D27: =D20+D21 -> 189834.66 | E27: =E20+E21 -> 200878.36 | F27: =F20+F21 -> 143129.78 | G27: =G20+G21 -> 159688.59 | H27: =H20+H21 -> 170807.86 | I27: =IFERROR(__xludf.DUMMYFUNCTION("""COMPUTED_VALUE"""),185959) -> 185959 | J27: =IFERROR(__xludf.DUMMYFUNCTION("""COMPUTED_VALUE"""),275712.88) -> 275712.88 | K27: =IFERROR(__xludf.DUMMYFUNCTION("""COMPUTED_VALUE"""),0) -> 0 | L27: =IFERROR(__xludf.DUMMYFUNCTION("""COMPUTED_VALUE"""),0) -> 0 | M27: =IFERROR(__xludf.DUMMYFUNCTION("""COMPUTED_VALUE"""),0) -> 0 | N27: =IFERROR(__xludf.DUMMYFUNCTION("""COMPUTED_VALUE"""),0) -> 0 | P27: =C27+D27+E27+F27+G27+H27 -> 1035074.3 | Q27: =I27+J27+K27+L27+M27+N27 -> 461671.88 | R27: =Q27+P27 -> 1496746.2
B28: Despesas Operacionais | C28: =C29+C39+C60+C78 -> -112856.77 | D28: =D29+D39+D60+D78 -> -116364.79 | E28: =E29+E39+E60+E78 -> -94723.738 | F28: =F29+F39+F60+F78 -> -127896.35 | G28: =G29+G39+G60+G78 -> -87178.468 | H28: =H29+H39+H60+H78 -> -79811.647 | I28: =IFERROR(__xludf.DUMMYFUNCTION("""COMPUTED_VALUE"""),-133299.7567664) -> -133299.76 | J28: =IFERROR(__xludf.DUMMYFUNCTION("""COMPUTED_VALUE"""),-121493.3609235) -> -121493.36 | K28: =IFERROR(__xludf.DUMMYFUNCTION("""COMPUTED_VALUE"""),0) -> 0 | L28: =IFERROR(__xludf.DUMMYFUNCTION("""COMPUTED_VALUE"""),0) -> 0 | M28: =IFERROR(__xludf.DUMMYFUNCTION("""COMPUTED_VALUE"""),0) -> 0 | N28: =IFERROR(__xludf.DUMMYFUNCTION("""COMPUTED_VALUE"""),0) -> 0 | P28: =C28+D28+E28+F28+G28+H28 -> -618831.76 | Q28: =I28+J28+K28+L28+M28+N28 -> -254793.12 | R28: =Q28+P28 -> -873624.88
B29: Despesas de Vendas e Marketing | C29: =SUM(C30:C38) -> -41486.49 | D29: =SUM(D30:D38) -> -44933.63 | E29: =SUM(E30:E38) -> -31323.43 | F29: =SUM(F30:F38) -> -60289.29 | G29: =SUM(G30:G38) -> -31299.56 | H29: =SUM(H30:H38) -> -24522.11 | I29: =IFERROR(__xludf.DUMMYFUNCTION("""COMPUTED_VALUE"""),-44614.36) -> -44614.36 | J29: =IFERROR(__xludf.DUMMYFUNCTION("""COMPUTED_VALUE"""),-50519.15) -> -50519.15 | K29: =IFERROR(__xludf.DUMMYFUNCTION("""COMPUTED_VALUE"""),0) -> 0 | L29: =IFERROR(__xludf.DUMMYFUNCTION("""COMPUTED_VALUE"""),0) -> 0 | M29: =IFERROR(__xludf.DUMMYFUNCTION("""COMPUTED_VALUE"""),0) -> 0 | N29: =IFERROR(__xludf.DUMMYFUNCTION("""COMPUTED_VALUE"""),0) -> 0 | P29: =C29+D29+E29+F29+G29+H29 -> -233854.51 | Q29: =I29+J29+K29+L29+M29+N29 -> -95133.51 | R29: =Q29+P29 -> -328988.02
B30: Comissões de Vendas - Comercial | C30: -1451.13 | D30: -2288.75 | E30: -1783.99 | F30: -9302.58 | G30: -2014.09 | H30: -233.43 | I30: =IFERROR(__xludf.DUMMYFUNCTION("""COMPUTED_VALUE"""),-84.75) -> -84.75 | J30: =IFERROR(__xludf.DUMMYFUNCTION("""COMPUTED_VALUE"""),-390.18) -> -390.18 | P30: =C30+D30+E30+F30+G30+H30 -> -17073.97 | Q30: =I30+J30+K30+L30+M30+N30 -> -474.93 | R30: =Q30+P30 -> -17548.9
B31: Comissões de Performance - CS | C31: -8204.25 | D31: 0 | E31: 0 | F31: -12208.85 | G31: 0 | H31: 0 | I31: =IFERROR(__xludf.DUMMYFUNCTION("""COMPUTED_VALUE"""),-3390.02) -> -3390.02 | J31: =IFERROR(__xludf.DUMMYFUNCTION("""COMPUTED_VALUE"""),0) -> 0
B32: Marketing | C32: -15649 | D32: -2000 | E32: -2000 | F32: -4719 | G32: -12102.08 | H32: -2752.36 | I32: =IFERROR(__xludf.DUMMYFUNCTION("""COMPUTED_VALUE"""),-3402.36) -> -3402.36 | J32: =IFERROR(__xludf.DUMMYFUNCTION("""COMPUTED_VALUE"""),-4629.67) -> -4629.67 | P32: =C32+D32+E32+F32+G32+H32 -> -39222.44 | Q32: =I32+J32+K32+L32+M32+N32 -> -8032.03 | R32: =Q32+P32 -> -47254.47
B33: Despesas de Viagens | C33: 0 | D33: -5024.12 | E33: -1124.91 | F33: -3559.8 | G33: -580.01 | H33: -1466.5 | I33: =IFERROR(__xludf.DUMMYFUNCTION("""COMPUTED_VALUE"""),0) -> 0 | J33: =IFERROR(__xludf.DUMMYFUNCTION("""COMPUTED_VALUE"""),0) -> 0 | P33: =C33+D33+E33+F33+G33+H33 -> -11755.34 | Q33: =I33+J33+K33+L33+M33+N33 -> 0 | R33: =Q33+P33 -> -11755.34
B34: Cashback - Afiliados | C34: -553.65 | D34: -3109.05 | E34: -3018.19 | F34: =-3230.07-342.55 -> -3572.62 | G34: -3821.33 | H34: -1769.13 | I34: =IFERROR(__xludf.DUMMYFUNCTION("""COMPUTED_VALUE"""),-5015.91) -> -5015.91 | J34: =IFERROR(__xludf.DUMMYFUNCTION("""COMPUTED_VALUE"""),-1762.39) -> -1762.39 | P34: =C34+D34+E34+F34+G34+H34 -> -15843.97 | Q34: =I34+J34+K34+L34+M34+N34 -> -6778.3 | R34: =Q34+P34 -> -22622.27
B35: Cashback - Produtores | C35: -4571.17 | D35: -21204.02 | E35: -10487.02 | F35: =-10315.37-8464.81 -> -18780.18 | G35: -6501.84 | H35: -7321.28 | I35: =IFERROR(__xludf.DUMMYFUNCTION("""COMPUTED_VALUE"""),-9750.44) -> -9750.44 | J35: =IFERROR(__xludf.DUMMYFUNCTION("""COMPUTED_VALUE"""),-13677.71) -> -13677.71 | P35: =C35+D35+E35+F35+G35+H35 -> -68865.51 | Q35: =I35+J35+K35+L35+M35+N35 -> -23428.15 | R35: =Q35+P35 -> -92293.66
B36: Cashback - Franquias | C36: -11057.29 | D36: -11307.69 | E36: -12909.32 | F36: -8146.26 | G36: -6280.21 | H36: -10979.41 | I36: =IFERROR(__xludf.DUMMYFUNCTION("""COMPUTED_VALUE"""),-11485.44) -> -11485.44 | J36: =IFERROR(__xludf.DUMMYFUNCTION("""COMPUTED_VALUE"""),-15029.6) -> -15029.6 | P36: =C36+D36+E36+F36+G36+H36 -> -60680.18 | Q36: =I36+J36+K36+L36+M36+N36 -> -26515.04 | R36: =Q36+P36 -> -87195.22
B37: Cashback - Franqueadora Viva | C37: 0 | D37: 0 | E37: 0 | F37: 0 | G37: 0 | H37: 0 | I37: =IFERROR(__xludf.DUMMYFUNCTION("""COMPUTED_VALUE"""),-11485.44) -> -11485.44 | J37: =IFERROR(__xludf.DUMMYFUNCTION("""COMPUTED_VALUE"""),-15029.6) -> -15029.6
B38: Bonificações | C38: 0 | D38: 0 | E38: 0 | F38: 0 | G38: 0 | H38: 0 | I38: =IFERROR(__xludf.DUMMYFUNCTION("""COMPUTED_VALUE"""),0) -> 0 | J38: =IFERROR(__xludf.DUMMYFUNCTION("""COMPUTED_VALUE"""),0) -> 0 | K38: =IFERROR(__xludf.DUMMYFUNCTION("""COMPUTED_VALUE"""),0) -> 0 | L38: =IFERROR(__xludf.DUMMYFUNCTION("""COMPUTED_VALUE"""),0) -> 0 | M38: =IFERROR(__xludf.DUMMYFUNCTION("""COMPUTED_VALUE"""),0) -> 0 | N38: =IFERROR(__xludf.DUMMYFUNCTION("""COMPUTED_VALUE"""),0) -> 0 | P38: =C38+D38+E38+F38+G38+H38 -> 0 | Q38: =I38+J38+K38+L38+M38+N38 -> 0 | R38: =Q38+P38 -> 0
B39: Despesas com Pessoal | C39: =SUM(C40:C59) -> -55626.043 | D39: =SUM(D40:D59) -> -46514.461 | E39: =SUM(E40:E59) -> -48975.558 | F39: =SUM(F40:F59) -> -56419.866 | G39: =SUM(G40:G59) -> -46331.018 | H39: =SUM(H40:H59) -> -44563.497 | I39: =IFERROR(__xludf.DUMMYFUNCTION("""COMPUTED_VALUE"""),-76280.2267664) -> -76280.227 | J39: =IFERROR(__xludf.DUMMYFUNCTION("""COMPUTED_VALUE"""),-57932.4209235) -> -57932.421 | K39: =IFERROR(__xludf.DUMMYFUNCTION("""COMPUTED_VALUE"""),0) -> 0 | L39: =IFERROR(__xludf.DUMMYFUNCTION("""COMPUTED_VALUE"""),0) -> 0 | M39: =IFERROR(__xludf.DUMMYFUNCTION("""COMPUTED_VALUE"""),0) -> 0 | N39: =IFERROR(__xludf.DUMMYFUNCTION("""COMPUTED_VALUE"""),0) -> 0 | P39: =C39+D39+E39+F39+G39+H39 -> -298430.44 | Q39: =I39+J39+K39+L39+M39+N39 -> -134212.65 | R39: =Q39+P39 -> -432643.09
B40: Salários | C40: -25834.61 | D40: =-3999.62-27516.6 -> -31516.22 | E40: =-26958.56-5022 -> -31980.56 | F40: =-31033.49-6539 -> -37572.49 | G40: -29802.63 | H40: -29662.51 | I40: =IFERROR(__xludf.DUMMYFUNCTION("""COMPUTED_VALUE"""),-24281.12) -> -24281.12 | J40: =IFERROR(__xludf.DUMMYFUNCTION("""COMPUTED_VALUE"""),-28152.55) -> -28152.55 | P40: =C40+D40+E40+F40+G40+H40 -> -186369.02 | Q40: =I40+J40+K40+L40+M40+N40 -> -52433.67 | R40: =Q40+P40 -> -238802.69
B41: Contratados Pessoa Jurídicas | C41: 0 | D41: 0 | E41: 0 | F41: 0 | I41: =IFERROR(__xludf.DUMMYFUNCTION("""COMPUTED_VALUE"""),0) -> 0 | J41: =IFERROR(__xludf.DUMMYFUNCTION("""COMPUTED_VALUE"""),0) -> 0 | K41: =IFERROR(__xludf.DUMMYFUNCTION("""COMPUTED_VALUE"""),0) -> 0 | L41: =IFERROR(__xludf.DUMMYFUNCTION("""COMPUTED_VALUE"""),0) -> 0 | M41: =IFERROR(__xludf.DUMMYFUNCTION("""COMPUTED_VALUE"""),0) -> 0 | N41: =IFERROR(__xludf.DUMMYFUNCTION("""COMPUTED_VALUE"""),0) -> 0 | P41: =C41+D41+E41+F41+G41+H41 -> 0 | Q41: =I41+J41+K41+L41+M41+N41 -> 0 | R41: =Q41+P41 -> 0
...

Sheet ORÇADO X REALIZADO
C4: Demonstrativos Financeiros - 2026 Consolidado | D4: JANEIRO | G4: FEVEREIRO | J4: MARÇO | M4: ABRIL | P4: MAIO | S4: JUNHO | V4: JULHO | Y4: AGOSTO | AB4: SETEMBRO | AE4: OUTUBRO | AH4: NOVEMBRO | AK4: DEZEMBRO | AO4: 1 SEM | AR4: 2 SEM | AU4: 2025
C6: DRE (R$) | D6: Orçado | E6: Realizado | F6: % | G6: Orçado | H6: Realizado | I6: % | J6: Orçado | K6: Realizado | L6: % | M6: Orçado | N6: Realizado | O6: % | P6: Orçado | Q6: Realizado | R6: % | S6: Orçado | T6: Realizado | U6: % | V6: Orçado | W6: Realizado | X6: % | Y6: Orçado | Z6: Realizado | AA6: % | AB6: Orçado | AC6: Realizado | AD6: % | AE6: Orçado | AF6: Realizado | AG6: % | AH6: Orçado | AI6: Realizado | AJ6: % | AK6: Orçado | AL6: Realizado | AM6: % | AO6: Orçado | AP6: Realizado | AQ6: % | AR6: Orçado | AS6: Realizado | AT6: % | AU6: Orçado | AV6: Realizado | AW6: %
C7: Receita Operacional Bruta | D7: =Orçamento!B4 -> 321190.32 | E7: ='DRE 2026'!C4 -> 276257.97 | F7: =IF(D7=0, IF(E7=0, 0, 100%), (E7 - D7) / D7) -> -0.13989321 | G7: =Orçamento!C4 -> 262827.35 | H7: ='DRE 2026'!D4 -> 302537.98 | I7: =IF(G7=0, IF(H7=0, 0, 100%), (H7 - G7) / G7) -> 0.15109017 | J7: =Orçamento!D4 -> 353083.28 | K7: ='DRE 2026'!E4 -> 297990.92 | L7: =IF(J7=0, IF(K7=0, 0, 100%), (K7 - J7) / J7) -> -0.15603219 | M7: =Orçamento!E4 -> 284073.18 | N7: ='DRE 2026'!F4 -> 235626.88 | O7: =IF(M7=0, IF(N7=0, 0, 100%), (N7 - M7) / M7) -> -0.17054163 | P7: =Orçamento!F4 -> 359398.21 | Q7: ='DRE 2026'!G4 -> 242586.46 | R7: =IF(P7=0, IF(Q7=0, 0, 100%), (Q7 - P7) / P7) -> -0.32502041 | S7: =Orçamento!G4 -> 304639.77 | T7: ='DRE 2026'!H4 -> 283604.11 | U7: =IF(S7=0, IF(T7=0, 0, 100%), (T7 - S7) / S7) -> -0.069050937 | V7: =Orçamento!H4 -> 387575.87 | W7: ='DRE 2026'!I4 -> 305701.16 | X7: =IF(V7=0, IF(W7=0, 0, 100%), (W7 - V7) / V7) -> -0.21124821 | Y7: =Orçamento!I4 -> 403534.1 | Z7: ='DRE 2026'!J4 -> 414516.74 | AA7: =IF(Y7=0, IF(Z7=0, 0, 100%), (Z7 - Y7) / Y7) -> 0.027216149 | AB7: =Orçamento!J4 -> 339417.39 | AC7: ='DRE 2026'!K4 -> 0 | AD7: =IF(AB7=0, IF(AC7=0, 0, 100%), (AC7 - AB7) / AB7) -> -1 | AE7: =Orçamento!K4 -> 327122.5 | AF7: ='DRE 2026'!L4 -> 0 | AG7: =IF(AE7=0, IF(AF7=0, 0, 100%), (AF7 - AE7) / AE7) -> -1 | AH7: =Orçamento!L4 -> 383439.94 | AI7: ='DRE 2026'!M4 -> 0 | AJ7: =IF(AH7=0, IF(AI7=0, 0, 100%), (AI7 - AH7) / AH7) -> -1 | AK7: =Orçamento!M4 -> 402871.03 | AL7: ='DRE 2026'!N4 -> 0 | AM7: =IF(AK7=0, IF(AL7=0, 0, 100%), (AL7 - AK7) / AK7) -> -1 | AO7: =IF($H$7=0,D7,IF($K$7=0,D7+G7,IF($N$7=0,D7+G7+J7,IF($Q$7=0,D7+G7+J7+M7,IF($T$7=0,D7+G7+J7+M7+P7,D7+G7+J7+M7+P7+S7))))) -> 1885212.1 | AP7: =IF($H$7=0,E7,IF($K$7=0,E7+H7,IF($N$7=0,E7+H7+K7,IF($Q$7=0,E7+H7+K7+N7,IF($T$7=0,E7+H7+K7+N7+Q7,E7+H7+K7+N7+Q7+T7))))) -> 1638604.3 | AQ7: =IF(AO7=0, IF(AP7=0, 0, 100%), (AP7 - AO7) / AO7) -> -0.13081169 | AR7: =IF($Z$7=0,V7,IF($AC$7=0,V7+Y7,IF($AF$7=0,V7+Y7+AB7,IF($AI$7=0,V7+Y7+AB7+AE7,IF($AL$7=0,V7+Y7+AB7+AE7+AH7,V7+Y7+AB7+AE7+AH7+AK7))))) -> 791109.96 | AS7: =IF($Z$7=0,W7,IF($AC$7=0,W7+Z7,IF($AF$7=0,W7+Z7+AC7,IF($AI$7=0,W7+Z7+AC7+AF7,IF($AL$7=0,W7+Z7+AC7+AF7+AI7,W7+Z7+AC7+AF7+AI7+AL7))))) -> 720217.9 | AT7: =IF(AR7=0, IF(AS7=0, 0, 100%), (AS7 - AR7) / AR7) -> -0.089610885 | AU7: =AR7+AO7 -> 2676322.1 | AV7: =AP7+AS7 -> 2358822.2 | AW7: =IF(AU7=0, IF(AV7=0, 0, 100%), (AV7 - AU7) / AU7) -> -0.1186329
C8: Receita com Taxa de Vendas Online - Formaturas | D8: =Orçamento!B5 -> 146619.93 | E8: ='DRE 2026'!C5 -> 110204.65 | F8: =IF(D8=0, IF(E8=0, 0, 100%), (E8 - D8) / D8) -> -0.24836513 | G8: =Orçamento!C5 -> 85759.094 | H8: ='DRE 2026'!D5 -> 125561.86 | I8: =IF(G8=0, IF(H8=0, 0, 100%), (H8 - G8) / G8) -> 0.46412297 | J8: =Orçamento!D5 -> 130922.08 | K8: ='DRE 2026'!E5 -> 101436.85 | L8: =IF(J8=0, IF(K8=0, 0, 100%), (K8 - J8) / J8) -> -0.22521203 | M8: =Orçamento!E5 -> 89831.148 | N8: ='DRE 2026'!F5 -> 64504.04 | O8: =IF(M8=0, IF(N8=0, 0, 100%), (N8 - M8) / M8) -> -0.28194127 | P8: =Orçamento!F5 -> 106962.46 | Q8: ='DRE 2026'!G5 -> 62018.63 | R8: =IF(P8=0, IF(Q8=0, 0, 100%), (Q8 - P8) / P8) -> -0.42018319 | S8: =Orçamento!G5 -> 89356.023 | T8: ='DRE 2026'!H5 -> 85436.05 | U8: =IF(S8=0, IF(T8=0, 0, 100%), (T8 - S8) / S8) -> -0.043869156 | V8: =Orçamento!H5 -> 123696.26 | W8: ='DRE 2026'!I5 -> 92571.47 | X8: =IF(V8=0, IF(W8=0, 0, 100%), (W8 - V8) / V8) -> -0.25162274 | Y8: =Orçamento!I5 -> 147094.86 | Z8: ='DRE 2026'!J5 -> 146550.37 | AA8: =IF(Y8=0, IF(Z8=0, 0, 100%), (Z8 - Y8) / Y8) -> -0.0037016384 | AB8: =Orçamento!J5 -> 135253.9 | AC8: ='DRE 2026'!K5 -> 0 | AD8: =IF(AB8=0, IF(AC8=0, 0, 100%), (AC8 - AB8) / AB8) -> -1 | AE8: =Orçamento!K5 -> 136690.55 | AF8: ='DRE 2026'!L5 -> 0 | AG8: =IF(AE8=0, IF(AF8=0, 0, 100%), (AF8 - AE8) / AE8) -> -1 | AH8: =Orçamento!L5 -> 183799.02 | AI8: ='DRE 2026'!M5 -> 0 | AJ8: =IF(AH8=0, IF(AI8=0, 0, 100%), (AI8 - AH8) / AH8) -> -1 | AK8: =Orçamento!M5 -> 191838.4 | AL8: ='DRE 2026'!N5 -> 0 | AM8: =IF(AK8=0, IF(AL8=0, 0, 100%), (AL8 - AK8) / AK8) -> -1 | AO8: =IF(H8=0,D8,IF(K8=0,D8+G8,IF(N8=0,D8+G8+J8,IF(Q8=0,D8+G8+J8+M8,IF(T8=0,D8+G8+J8+M8+P8,D8+G8+J8+M8+P8+S8))))) -> 649450.73 | AP8: =IF($H$7=0,E8,IF($K$7=0,E8+H8,IF($N$7=0,E8+H8+K8,IF($Q$7=0,E8+H8+K8+N8,IF($T$7=0,E8+H8+K8+N8+Q8,E8+H8+K8+N8+Q8+T8))))) -> 549162.08 | AQ8: =IF(AO8=0, IF(AP8=0, 0, 100%), (AP8 - AO8) / AO8) -> -0.15442072 | AR8: =IF($Z$7=0,V8,IF($AC$7=0,V8+Y8,IF($AF$7=0,V8+Y8+AB8,IF($AI$7=0,V8+Y8+AB8+AE8,IF($AL$7=0,V8+Y8+AB8+AE8+AH8,V8+Y8+AB8+AE8+AH8+AK8))))) -> 270791.12 | AS8: =IF($Z$7=0,W8,IF($AC$7=0,W8+Z8,IF($AF$7=0,W8+Z8+AC8,IF($AI$7=0,W8+Z8+AC8+AF8,IF($AL$7=0,W8+Z8+AC8+AF8+AI8,W8+Z8+AC8+AF8+AI8+AL8))))) -> 239121.84 | AT8: =IF(AR8=0, IF(AS8=0, 0, 100%), (AS8 - AR8) / AR8) -> -0.11695097 | AU8: =AR8+AO8 -> 920241.85 | AV8: =AP8+AS8 -> 788283.92 | AW8: =IF(AU8=0, IF(AV8=0, 0, 100%), (AV8 - AU8) / AU8) -> -0.14339484
C9: Receita com Taxa de Parcelamento Online - Formaturas | D9: =Orçamento!B6 -> 79122.699 | E9: ='DRE 2026'!C6 -> 80333.42 | F9: =IF(D9=0, IF(E9=0, 0, 100%), (E9 - D9) / D9) -> 0.015301822 | G9: =Orçamento!C6 -> 46049.808 | H9: ='DRE 2026'!D6 -> 81422.18 | I9: =IF(G9=0, IF(H9=0, 0, 100%), (H9 - G9) / G9) -> 0.7681329 | J9: =Orçamento!D6 -> 69637.414 | K9: ='DRE 2026'!E6 -> 72656.14 | L9: =IF(J9=0, IF(K9=0, 0, 100%), (K9 - J9) / J9) -> 0.043349198 | M9: =Orçamento!E6 -> 48000.699 | N9: ='DRE 2026'!F6 -> 39955.32 | O9: =IF(M9=0, IF(N9=0, 0, 100%), (N9 - M9) / M9) -> -0.16760962 | P9: =Orçamento!F6 -> 57057.708 | Q9: ='DRE 2026'!G6 -> 42199.76 | R9: =IF(P9=0, IF(Q9=0, 0, 100%), (Q9 - P9) / P9) -> -0.26040212 | S9: =Orçamento!G6 -> 48289.561 | T9: ='DRE 2026'!H6 -> 57866.42 | U9: =IF(S9=0, IF(T9=0, 0, 100%), (T9 - S9) / S9) -> 0.19832153 | V9: =Orçamento!H6 -> 66487.669 | W9: ='DRE 2026'!I6 -> 66241.41 | X9: =IF(V9=0, IF(W9=0, 0, 100%), (W9 - V9) / V9) -> -0.0037038336 | Y9: =Orçamento!I6 -> 79031.323 | Z9: ='DRE 2026'!J6 -> 100191.14 | AA9: =IF(Y9=0, IF(Z9=0, 0, 100%), (Z9 - Y9) / Y9) -> 0.26773962 | AB9: =Orçamento!J6 -> 72637.338 | AC9: ='DRE 2026'!K6 -> 0 | AD9: =IF(AB9=0, IF(AC9=0, 0, 100%), (AC9 - AB9) / AB9) -> -1 | AE9: =Orçamento!K6 -> 74004.077 | AF9: ='DRE 2026'!L6 -> 0 | AG9: =IF(AE9=0, IF(AF9=0, 0, 100%), (AF9 - AE9) / AE9) -> -1 | AH9: =Orçamento!L6 -> 99292.901 | AI9: ='DRE 2026'!M6 -> 0 | AJ9: =IF(AH9=0, IF(AI9=0, 0, 100%), (AI9 - AH9) / AH9) -> -1 | AK9: =Orçamento!M6 -> 104769.79 | AL9: ='DRE 2026'!N6 -> 0 | AM9: =IF(AK9=0, IF(AL9=0, 0, 100%), (AL9 - AK9) / AK9) -> -1 | AO9: =IF(H9=0,D9,IF(K9=0,D9+G9,IF(N9=0,D9+G9+J9,IF(Q9=0,D9+G9+J9+M9,IF(T9=0,D9+G9+J9+M9+P9,D9+G9+J9+M9+P9+S9))))) -> 348157.89 | AP9: =IF(H9=0,E9,IF(K9=0,E9+H9,IF(N9=0,K9+H9+E9,IF(Q9=0,N9+K9+H9+E9,IF(T9<>0,T9+Q9+N9+K9+H9+E9,Q9+N9+K9+H9+E9))))) -> 374433.24 | AQ9: =IF(AO9=0, IF(AP9=0, 0, 100%), (AP9 - AO9) / AO9) -> 0.075469645 | AR9: =IF($Z$7=0,V9,IF($AC$7=0,V9+Y9,IF($AF$7=0,V9+Y9+AB9,IF($AI$7=0,V9+Y9+AB9+AE9,IF($AL$7=0,V9+Y9+AB9+AE9+AH9,V9+Y9+AB9+AE9+AH9+AK9))))) -> 145518.99 | AS9: =IF($Z$7=0,W9,IF($AC$7=0,W9+Z9,IF($AF$7=0,W9+Z9+AC9,IF($AI$7=0,W9+Z9+AC9+AF9,IF($AL$7=0,W9+Z9+AC9+AF9+AI9,W9+Z9+AC9+AF9+AI9+AL9))))) -> 166432.55 | AT9: =IF(AR9=0, IF(AS9=0, 0, 100%), (AS9 - AR9) / AR9) -> 0.14371703 | AU9: =AR9+AO9 -> 493676.88 | AV9: =AP9+AS9 -> 540865.79 | AW9: =IF(AU9=0, IF(AV9=0, 0, 100%), (AV9 - AU9) / AU9) -> 0.09558663
C10: Receita com Taxa de Vendas Online - Eventos em Geral | D10: =Orçamento!B7 -> 68688.24 | E10: ='DRE 2026'!C7 -> 63839.69 | F10: =IF(D10=0, IF(E10=0, 0, 100%), (E10 - D10) / D10) -> -0.070587775 | G10: =Orçamento!C7 -> 94286.48 | H10: ='DRE 2026'!D7 -> 62635.2 | I10: =IF(G10=0, IF(H10=0, 0, 100%), (H10 - G10) / G10) -> -0.33569267 | J10: =Orçamento!D7 -> 109762.64 | K10: ='DRE 2026'!E7 -> 88391.41 | L10: =IF(J10=0, IF(K10=0, 0, 100%), (K10 - J10) / J10) -> -0.19470405 | M10: =Orçamento!E7 -> 105241.52 | N10: ='DRE 2026'!F7 -> 92904.64 | O10: =IF(M10=0, IF(N10=0, 0, 100%), (N10 - M10) / M10) -> -0.11722446 | P10: =Orçamento!F7 -> 140602.4 | Q10: ='DRE 2026'!G7 -> 101577.49 | R10: =IF(P10=0, IF(Q10=0, 0, 100%), (Q10 - P10) / P10) -> -0.27755508 | S10: =Orçamento!G7 -> 120176.16 | T10: ='DRE 2026'!H7 -> 93967.24 | U10: =IF(S10=0, IF(T10=0, 0, 100%), (T10 - S10) / S10) -> -0.21808751 | V10: =Orçamento!H7 -> 142051.68 | W10: ='DRE 2026'!I7 -> 103254.14 | X10: =IF(V10=0, IF(W10=0, 0, 100%), (W10 - V10) / V10) -> -0.27312271 | Y10: =Orçamento!I7 -> 127670.32 | Z10: ='DRE 2026'!J7 -> 121923.04 | AA10: =IF(Y10=0, IF(Z10=0, 0, 100%), (Z10 - Y10) / Y10) -> -0.045016571 | AB10: =Orçamento!J7 -> 94651.84 | AC10: ='DRE 2026'!K7 -> 0 | AD10: =IF(AB10=0, IF(AC10=0, 0, 100%), (AC10 - AB10) / AB10) -> -1 | AE10: =Orçamento!K7 -> 83786.48 | AF10: ='DRE 2026'!L7 -> 0 | AG10: =IF(AE10=0, IF(AF10=0, 0, 100%), (AF10 - AE10) / AE10) -> -1 | AH10: =Orçamento!L7 -> 72214.72 | AI10: ='DRE 2026'!M7 -> 0 | AJ10: =IF(AH10=0, IF(AI10=0, 0, 100%), (AI10 - AH10) / AH10) -> -1 | AK10: =Orçamento!M7 -> 76471.28 | AL10: ='DRE 2026'!N7 -> 0 | AM10: =IF(AK10=0, IF(AL10=0, 0, 100%), (AL10 - AK10) / AK10) -> -1 | AO10: =IF(H10=0,D10,IF(K10=0,D10+G10,IF(N10=0,D10+G10+J10,IF(Q10=0,D10+G10+J10+M10,IF(T10=0,D10+G10+J10+M10+P10,D10+G10+J10+M10+P10+S10))))) -> 638757.44 | AP10: =IF($H$7=0,E10,IF($K$7=0,E10+H10,IF($N$7=0,E10+H10+K10,IF($Q$7=0,E10+H10+K10+N10,IF($T$7=0,E10+H10+K10+N10+Q10,E10+H10+K10+N10+Q10+T10))))) -> 503315.67 | AQ10: =IF(AO10=0, IF(AP10=0, 0, 100%), (AP10 - AO10) / AO10) -> -0.21203944 | AR10: =IF($Z$7=0,V10,IF($AC$7=0,V10+Y10,IF($AF$7=0,V10+Y10+AB10,IF($AI$7=0,V10+Y10+AB10+AE10,IF($AL$7=0,V10+Y10+AB10+AE10+AH10,V10+Y10+AB10+AE10+AH10+AK10))))) -> 269722 | AS10: =IF($Z$7=0,W10,IF($AC$7=0,W10+Z10,IF($AF$7=0,W10+Z10+AC10,IF($AI$7=0,W10+Z10+AC10+AF10,IF($AL$7=0,W10+Z10+AC10+AF10+AI10,W10+Z10+AC10+AF10+AI10+AL10))))) -> 225177.18 | AT10: =IF(AR10=0, IF(AS10=0, 0, 100%), (AS10 - AR10) / AR10) -> -0.16515086 | AU10: =AR10+AO10 -> 908479.44 | AV10: =AP10+AS10 -> 728492.85 | AW10: =IF(AU10=0, IF(AV10=0, 0, 100%), (AV10 - AU10) / AU10) -> -0.19811851
C11: Receita com Taxa de Parcelamento Online - Eventos em Geral | D11: =Orçamento!B8 -> 14836.66 | E11: ='DRE 2026'!C8 -> 13800.06 | F11: =IF(D11=0, IF(E11=0, 0, 100%), (E11 - D11) / D11) -> -0.069867467 | G11: =Orçamento!C8 -> 20365.88 | H11: ='DRE 2026'!D8 -> 21745.76 | I11: =IF(G11=0, IF(H11=0, 0, 100%), (H11 - G11) / G11) -> 0.067754516 | J11: =Orçamento!D8 -> 23708.73 | K11: ='DRE 2026'!E8 -> 25291.26 | L11: =IF(J11=0, IF(K11=0, 0, 100%), (K11 - J11) / J11) -> 0.06674882 | M11: =Orçamento!E8 -> 22732.168 | N11: ='DRE 2026'!F8 -> 27044.99 | O11: =IF(M11=0, IF(N11=0, 0, 100%), (N11 - M11) / M11) -> 0.18972329 | P11: =Orçamento!F8 -> 30370.118 | Q11: ='DRE 2026'!G8 -> 22268.77 | R11: =IF(P11=0, IF(Q11=0, 0, 100%), (Q11 - P11) / P11) -> -0.26675393 | S11: =Orçamento!G8 -> 25958.051 | T11: ='DRE 2026'!H8 -> 29541.43 | U11: =IF(S11=0, IF(T11=0, 0, 100%), (T11 - S11) / S11) -> 0.13804501 | V11: =Orçamento!H8 -> 30683.163 | W11: ='DRE 2026'!I8 -> 28964.19 | X11: =IF(V11=0, IF(W11=0, 0, 100%), (W11 - V11) / V11) -> -0.056023327 | Y11: =Orçamento!I8 -> 27576.789 | Z11: ='DRE 2026'!J8 -> 31761.79 | AA11: =IF(Y11=0, IF(Z11=0, 0, 100%), (Z11 - Y11) / Y11) -> 0.15175809 | AB11: =Orçamento!J8 -> 20444.797 | AC11: ='DRE 2026'!K8 -> 0 | AD11: =IF(AB11=0, IF(AC11=0, 0, 100%), (AC11 - AB11) / AB11) -> -1 | AE11: =Orçamento!K8 -> 18097.88 | AF11: ='DRE 2026'!L8 -> 0 | AG11: =IF(AE11=0, IF(AF11=0, 0, 100%), (AF11 - AE11) / AE11) -> -1 | AH11: =Orçamento!L8 -> 15598.38 | AI11: ='DRE 2026'!M8 -> 0 | AJ11: =IF(AH11=0, IF(AI11=0, 0, 100%), (AI11 - AH11) / AH11) -> -1 | AK11: =Orçamento!M8 -> 16517.796 | AL11: ='DRE 2026'!N8 -> 0 | AM11: =IF(AK11=0, IF(AL11=0, 0, 100%), (AL11 - AK11) / AK11) -> -1 | AO11: =IF(H11=0,D11,IF(K11=0,D11+G11,IF(N11=0,D11+G11+J11,IF(Q11=0,D11+G11+J11+M11,IF(T11=0,D11+G11+J11+M11+P11,D11+G11+J11+M11+P11+S11))))) -> 137971.61 | AP11: =IF($H$7=0,E11,IF($K$7=0,E11+H11,IF($N$7=0,E11+H11+K11,IF($Q$7=0,E11+H11+K11+N11,IF($T$7=0,E11+H11+K11+N11+Q11,E11+H11+K11+N11+Q11+T11))))) -> 139692.27 | AQ11: =IF(AO11=0, IF(AP11=0, 0, 100%), (AP11 - AO11) / AO11) -> 0.012471138 | AR11: =IF($Z$7=0,V11,IF($AC$7=0,V11+Y11,IF($AF$7=0,V11+Y11+AB11,IF($AI$7=0,V11+Y11+AB11+AE11,IF($AL$7=0,V11+Y11+AB11+AE11+AH11,V11+Y11+AB11+AE11+AH11+AK11))))) -> 58259.952 | AS11: =IF($Z$7=0,W11,IF($AC$7=0,W11+Z11,IF($AF$7=0,W11+Z11+AC11,IF($AI$7=0,W11+Z11+AC11+AF11,IF($AL$7=0,W11+Z11+AC11+AF11+AI11,W11+Z11+AC11+AF11+AI11+AL11))))) -> 60725.98 | AT11: =IF(AR11=0, IF(AS11=0, 0, 100%), (AS11 - AR11) / AR11) -> 0.042328013 | AU11: =AR11+AO11 -> 196231.56 | AV11: =AP11+AS11 -> 200418.25 | AW11: =IF(AU11=0, IF(AV11=0, 0, 100%), (AV11 - AU11) / AU11) -> 0.021335462
C12: Receita com Taxa de Cartão | D12: =Orçamento!B9 -> 0 | E12: ='DRE 2026'!C9 -> 2006 | F12: =IF(D12=0, IF(E12=0, 0, 100%), (E12 - D12) / D12) -> 1 | G12: =Orçamento!C9 -> 0 | H12: ='DRE 2026'!D9 -> 3700 | I12: =IF(G12=0, IF(H12=0, 0, 100%), (H12 - G12) / G12) -> 1 | J12: =Orçamento!D9 -> 0 | K12: ='DRE 2026'!E9 -> 2166 | L12: =IF(J12=0, IF(K12=0, 0, 100%), (K12 - J12) / J12) -> 1 | M12: =Orçamento!E9 -> 0 | N12: ='DRE 2026'!F9 -> 2562 | O12: =IF(M12=0, IF(N12=0, 0, 100%), (N12 - M12) / M12) -> 1 | P12: =Orçamento!F9 -> 0 | Q12: ='DRE 2026'!G9 -> 4442 | R12: =IF(P12=0, IF(Q12=0, 0, 100%), (Q12 - P12) / P12) -> 1 | S12: =Orçamento!G9 -> 0 | T12: ='DRE 2026'!H9 -> 2643 | U12: =IF(S12=0, IF(T12=0, 0, 100%), (T12 - S12) / S12) -> 1 | V12: =Orçamento!H9 -> 0 | W12: ='DRE 2026'!I9 -> 878 | X12: =IF(V12=0, IF(W12=0, 0, 100%), (W12 - V12) / V12) -> 1 | Y12: =Orçamento!I9 -> 0 | Z12: ='DRE 2026'!J9 -> 2504 | AA12: =IF(Y12=0, IF(Z12=0, 0, 100%), (Z12 - Y12) / Y12) -> 1 | AB12: =Orçamento!J9 -> 0 | AC12: ='DRE 2026'!K9 -> 0 | AD12: =IF(AB12=0, IF(AC12=0, 0, 100%), (AC12 - AB12) / AB12) -> 0 | AE12: =Orçamento!K9 -> 0 | AF12: ='DRE 2026'!L9 -> 0 | AG12: =IF(AE12=0, IF(AF12=0, 0, 100%), (AF12 - AE12) / AE12) -> 0 | AH12: =Orçamento!L9 -> 0 | AI12: ='DRE 2026'!M9 -> 0 | AJ12: =IF(AH12=0, IF(AI12=0, 0, 100%), (AI12 - AH12) / AH12) -> 0 | AK12: =Orçamento!M9 -> 0 | AL12: ='DRE 2026'!N9 -> 0 | AM12: =IF(AK12=0, IF(AL12=0, 0, 100%), (AL12 - AK12) / AK12) -> 0 | AO12: =IF(H12=0,D12,IF(K12=0,D12+G12,IF(N12=0,D12+G12+J12,IF(Q12=0,D12+G12+J12+M12,IF(T12=0,D12+G12+J12+M12+P12,D12+G12+J12+M12+P12+S12))))) -> 0 | AP12: =IF($H$7=0,E12,IF($K$7=0,E12+H12,IF($N$7=0,E12+H12+K12,IF($Q$7=0,E12+H12+K12+N12,IF($T$7=0,E12+H12+K12+N12+Q12,E12+H12+K12+N12+Q12+T12))))) -> 17519 | AQ12: =IF(AO12=0, IF(AP12=0, 0, 100%), (AP12 - AO12) / AO12) -> 1 | AR12: =IF($Z$7=0,V12,IF($AC$7=0,V12+Y12,IF($AF$7=0,V12+Y12+AB12,IF($AI$7=0,V12+Y12+AB12+AE12,IF($AL$7=0,V12+Y12+AB12+AE12+AH12,V12+Y12+AB12+AE12+AH12+AK12))))) -> 0 | AS12: =IF($Z$7=0,W12,IF($AC$7=0,W12+Z12,IF($AF$7=0,W12+Z12+AC12,IF($AI$7=0,W12+Z12+AC12+AF12,IF($AL$7=0,W12+Z12+AC12+AF12+AI12,W12+Z12+AC12+AF12+AI12+AL12))))) -> 3382 | AT12: =IF(AR12=0, IF(AS12=0, 0, 100%), (AS12 - AR12) / AR12) -> 1 | AU12: =AR12+AO12 -> 0 | AV12: =AP12+AS12 -> 20901 | AW12: =IF(AU12=0, IF(AV12=0, 0, 100%), (AV12 - AU12) / AU12) -> 1
C13: Receita com Taxa de Administração | D13: =Orçamento!B10 -> 3570.5844 | E13: ='DRE 2026'!C10 -> 1098.25 | F13: =IF(D13=0, IF(E13=0, 0, 100%), (E13 - D13) / D13) -> -0.69241729 | G13: =Orçamento!C10 -> 4901.2441 | H13: ='DRE 2026'!D10 -> 1452 | I13: =IF(G13=0, IF(H13=0, 0, 100%), (H13 - G13) / G13) -> -0.70374869 | J13: =Orçamento!D10 -> 5705.7331 | K13: ='DRE 2026'!E10 -> 1823.7 | L13: =IF(J13=0, IF(K13=0, 0, 100%), (K13 - J13) / J13) -> -0.68037411 | M13: =Orçamento!E10 -> 5470.7141 | N13: ='DRE 2026'!F10 -> 1539.7 | O13: =IF(M13=0, IF(N13=0, 0, 100%), (N13 - M13) / M13) -> -0.71855594 | P13: =Orçamento!F10 -> 7308.86 | Q13: ='DRE 2026'!G10 -> 1894.79 | R13: =IF(P13=0, IF(Q13=0, 0, 100%), (Q13 - P13) / P13) -> -0.74075437 | S13: =Orçamento!G10 -> 6247.0536 | T13: ='DRE 2026'!H10 -> 3814.95 | U13: =IF(S13=0, IF(T13=0, 0, 100%), (T13 - S13) / S13) -> -0.38932011 | V13: =Orçamento!H10 -> 7384.1972 | W13: ='DRE 2026'!I10 -> 1167.6 | X13: =IF(V13=0, IF(W13=0, 0, 100%), (W13 - V13) / V13) -> -0.84187855 | Y13: =Orçamento!I10 -> 6636.6186 | Z13: ='DRE 2026'!J10 -> 2062.4 | AA13: =IF(Y13=0, IF(Z13=0, 0, 100%), (Z13 - Y13) / Y13) -> -0.68923933 | AB13: =Orçamento!J10 -> 4920.2364 | AC13: ='DRE 2026'!K10 -> 0 | AD13: =IF(AB13=0, IF(AC13=0, 0, 100%), (AC13 - AB13) / AB13) -> -1 | AE13: =Orçamento!K10 -> 4355.4282 | AF13: ='DRE 2026'!L10 -> 0 | AG13: =IF(AE13=0, IF(AF13=0, 0, 100%), (AF13 - AE13) / AE13) -> -1 | AH13: =Orçamento!L10 -> 3753.8995 | AI13: ='DRE 2026'!M10 -> 0 | AJ13: =IF(AH13=0, IF(AI13=0, 0, 100%), (AI13 - AH13) / AH13) -> -1 | AK13: =Orçamento!M10 -> 3975.166 | AL13: ='DRE 2026'!N10 -> 0 | AM13: =IF(AK13=0, IF(AL13=0, 0, 100%), (AL13 - AK13) / AK13) -> -1 | AO13: =IF(H13=0,D13,IF(K13=0,D13+G13,IF(N13=0,D13+G13+J13,IF(Q13=0,D13+G13+J13+M13,IF(T13=0,D13+G13+J13+M13+P13,D13+G13+J13+M13+P13+S13))))) -> 33204.189 | AP13: =IF($H$7=0,E13,IF($K$7=0,E13+H13,IF($N$7=0,E13+H13+K13,IF($Q$7=0,E13+H13+K13+N13,IF($T$7=0,E13+H13+K13+N13+Q13,E13+H13+K13+N13+Q13+T13))))) -> 11623.39 | AQ13: =IF(AO13=0, IF(AP13=0, 0, 100%), (AP13 - AO13) / AO13) -> -0.64994206 | AR13: =IF($Z$7=0,V13,IF($AC$7=0,V13+Y13,IF($AF$7=0,V13+Y13+AB13,IF($AI$7=0,V13+Y13+AB13+AE13,IF($AL$7=0,V13+Y13+AB13+AE13+AH13,V13+Y13+AB13+AE13+AH13+AK13))))) -> 14020.816 | AS13: =IF($Z$7=0,W13,IF($AC$7=0,W13+Z13,IF($AF$7=0,W13+Z13+AC13,IF($AI$7=0,W13+Z13+AC13+AF13,IF($AL$7=0,W13+Z13+AC13+AF13+AI13,W13+Z13+AC13+AF13+AI13+AL13))))) -> 3230 | AT13: =IF(AR13=0, IF(AS13=0, 0, 100%), (AS13 - AR13) / AR13) -> -0.76962824 | AU13: =AR13+AO13 -> 47225.005 | AV13: =AP13+AS13 -> 14853.39 | AW13: =IF(AU13=0, IF(AV13=0, 0, 100%), (AV13 - AU13) / AU13) -> -0.68547616
C14: Receita com Taxa de Processamento | D14: =Orçamento!B11 -> 6131.1123 | E14: ='DRE 2026'!C11 -> 4875.9 | F14: =IF(D14=0, IF(E14=0, 0, 100%), (E14 - D14) / D14) -> -0.20472832 | G14: =Orçamento!C11 -> 8416.0112 | H14: ='DRE 2026'!D11 -> 5461.52 | I14: =IF(G14=0, IF(H14=0, 0, 100%), (H14 - G14) / G14) -> -0.351056 | J14: =Orçamento!D11 -> 9797.4132 | K14: ='DRE 2026'!E11 -> 5920.56 | L14: =IF(J14=0, IF(K14=0, 0, 100%), (K14 - J14) / J14) -> -0.39570172 | M14: =Orçamento!E11 -> 9393.8581 | N14: ='DRE 2026'!F11 -> 6831.19 | O14: =IF(M14=0, IF(N14=0, 0, 100%), (N14 - M14) / M14) -> -0.27280251 | P14: =Orçamento!F11 -> 12550.17 | Q14: ='DRE 2026'!G11 -> 7684 | R14: =IF(P14=0, IF(Q14=0, 0, 100%), (Q14 - P14) / P14) -> -0.38773739 | S14: =Orçamento!G11 -> 10726.924 | T14: ='DRE 2026'!H11 -> 10060.02 | U14: =IF(S14=0, IF(T14=0, 0, 100%), (T14 - S14) / S14) -> -0.062171042 | V14: =Orçamento!H11 -> 12679.533 | W14: ='DRE 2026'!I11 -> 11539.62 | X14: =IF(V14=0, IF(W14=0, 0, 100%), (W14 - V14) / V14) -> -0.08990181 | Y14: =Orçamento!I11 -> 11395.853 | Z14: ='DRE 2026'!J11 -> 9314 | AA14: =IF(Y14=0, IF(Z14=0, 0, 100%), (Z14 - Y14) / Y14) -> -0.18268512 | AB14: =Orçamento!J11 -> 8448.6232 | AC14: ='DRE 2026'!K11 -> 0 | AD14: =IF(AB14=0, IF(AC14=0, 0, 100%), (AC14 - AB14) / AB14) -> -1 | AE14: =Orçamento!K11 -> 7478.7812 | AF14: ='DRE 2026'!L11 -> 0 | AG14: =IF(AE14=0, IF(AF14=0, 0, 100%), (AF14 - AE14) / AE14) -> -1 | AH14: =Orçamento!L11 -> 6445.8859 | AI14: ='DRE 2026'!M11 -> 0 | AJ14: =IF(AH14=0, IF(AI14=0, 0, 100%), (AI14 - AH14) / AH14) -> -1 | AK14: =Orçamento!M11 -> 6825.8265 | AL14: ='DRE 2026'!N11 -> 0 | AM14: =IF(AK14=0, IF(AL14=0, 0, 100%), (AL14 - AK14) / AK14) -> -1 | AO14: =IF(H14=0,D14,IF(K14=0,D14+G14,IF(N14=0,D14+G14+J14,IF(Q14=0,D14+G14+J14+M14,IF(T14=0,D14+G14+J14+M14+P14,D14+G14+J14+M14+P14+S14))))) -> 57015.489 | AP14: =IF($H$7=0,E14,IF($K$7=0,E14+H14,IF($N$7=0,E14+H14+K14,IF($Q$7=0,E14+H14+K14+N14,IF($T$7=0,E14+H14+K14+N14+Q14,E14+H14+K14+N14+Q14+T14))))) -> 40833.19 | AQ14: =IF(AO14=0, IF(AP14=0, 0, 100%), (AP14 - AO14) / AO14) -> -0.28382286 | AR14: =IF($Z$7=0,V14,IF($AC$7=0,V14+Y14,IF($AF$7=0,V14+Y14+AB14,IF($AI$7=0,V14+Y14+AB14+AE14,IF($AL$7=0,V14+Y14+AB14+AE14+AH14,V14+Y14+AB14+AE14+AH14+AK14))))) -> 24075.386 | AS14: =IF($Z$7=0,W14,IF($AC$7=0,W14+Z14,IF($AF$7=0,W14+Z14+AC14,IF($AI$7=0,W14+Z14+AC14+AF14,IF($AL$7=0,W14+Z14+AC14+AF14+AI14,W14+Z14+AC14+AF14+AI14+AL14))))) -> 20853.62 | AT14: =IF(AR14=0, IF(AS14=0, 0, 100%), (AS14 - AR14) / AR14) -> -0.1338199 | AU14: =AR14+AO14 -> 81090.875 | AV14: =AP14+AS14 -> 61686.81 | AW14: =IF(AU14=0, IF(AV14=0, 0, 100%), (AV14 - AU14) / AU14) -> -0.2392879
C15: Receita com Taxas de Antecipação | D15: =Orçamento!B12 -> 2221.0935 | E15: ='DRE 2026'!C12 -> 0 | F15: =IF(D15=0, IF(E15=0, 0, 100%), (E15 - D15) / D15) -> -1 | G15: =Orçamento!C12 -> 3048.8346 | H15: ='DRE 2026'!D12 -> 319.46 | I15: =IF(G15=0, IF(H15=0, 0, 100%), (H15 - G15) / G15) -> -0.89521898 | J15: =Orçamento!D12 -> 3549.2696 | K15: ='DRE 2026'!E12 -> 0 | L15: =IF(J15=0, IF(K15=0, 0, 100%), (K15 - J15) / J15) -> -1 | M15: =Orçamento!E12 -> 3403.0753 | N15: ='DRE 2026'!F12 -> 0 | O15: =IF(M15=0, IF(N15=0, 0, 100%), (N15 - M15) / M15) -> -1 | P15: =Orçamento!F12 -> 4546.4998 | Q15: ='DRE 2026'!G12 -> 327.02 | R15: =IF(P15=0, IF(Q15=0, 0, 100%), (Q15 - P15) / P15) -> -0.92807214 | S15: =Orçamento!G12 -> 3885.9997 | T15: ='DRE 2026'!H12 -> 0 | U15: =IF(S15=0, IF(T15=0, 0, 100%), (T15 - S15) / S15) -> -1 | V15: =Orçamento!H12 -> 4593.3635 | W15: ='DRE 2026'!I12 -> 949.73 | X15: =IF(V15=0, IF(W15=0, 0, 100%), (W15 - V15) / V15) -> -0.79323866 | Y15: =Orçamento!I12 -> 4128.3299 | Z15: ='DRE 2026'!J12 -> 0 | AA15: =IF(Y15=0, IF(Z15=0, 0, 100%), (Z15 - Y15) / Y15) -> -1 | AB15: =Orçamento!J12 -> 3060.6489 | AC15: ='DRE 2026'!K12 -> 0 | AD15: =IF(AB15=0, IF(AC15=0, 0, 100%), (AC15 - AB15) / AB15) -> -1 | AE15: =Orçamento!K12 -> 2709.3081 | AF15: ='DRE 2026'!L12 -> 0 | AG15: =IF(AE15=0, IF(AF15=0, 0, 100%), (AF15 - AE15) / AE15) -> -1 | AH15: =Orçamento!L12 -> 2335.1252 | AI15: ='DRE 2026'!M12 -> 0 | AJ15: =IF(AH15=0, IF(AI15=0, 0, 100%), (AI15 - AH15) / AH15) -> -1 | AK15: =Orçamento!M12 -> 2472.7648 | AL15: ='DRE 2026'!N12 -> 0 | AM15: =IF(AK15=0, IF(AL15=0, 0, 100%), (AL15 - AK15) / AK15) -> -1 | AO15: =IF(H15=0,D15,IF(K15=0,D15+G15,IF(N15=0,D15+G15+J15,IF(Q15=0,D15+G15+J15+M15,IF(T15=0,D15+G15+J15+M15+P15,D15+G15+J15+M15+P15+S15))))) -> 5269.9281 | AP15: =IF($H$7=0,E15,IF($K$7=0,E15+H15,IF($N$7=0,E15+H15+K15,IF($Q$7=0,E15+H15+K15+N15,IF($T$7=0,E15+H15+K15+N15+Q15,E15+H15+K15+N15+Q15+T15))))) -> 646.48 | AQ15: =IF(AO15=0, IF(AP15=0, 0, 100%), (AP15 - AO15) / AO15) -> -0.8773266 | AR15: =IF($Z$7=0,V15,IF($AC$7=0,V15+Y15,IF($AF$7=0,V15+Y15+AB15,IF($AI$7=0,V15+Y15+AB15+AE15,IF($AL$7=0,V15+Y15+AB15+AE15+AH15,V15+Y15+AB15+AE15+AH15+AK15))))) -> 8721.6934 | AS15: =IF($Z$7=0,W15,IF($AC$7=0,W15+Z15,IF($AF$7=0,W15+Z15+AC15,IF($AI$7=0,W15+Z15+AC15+AF15,IF($AL$7=0,W15+Z15+AC15+AF15+AI15,W15+Z15+AC15+AF15+AI15+AL15))))) -> 949.73 | AT15: =IF(AR15=0, IF(AS15=0, 0, 100%), (AS15 - AR15) / AR15) -> -0.89110716 | AU15: =AR15+AO15 -> 13991.621 | AV15: =AP15+AS15 -> 1596.21 | AW15: =IF(AU15=0, IF(AV15=0, 0, 100%), (AV15 - AU15) / AU15) -> -0.88591673
C16: Receita com Locação de Equipamentos | D16: =Orçamento!B13 -> 0 | E16: ='DRE 2026'!C13 -> 0 | F16: =IF(D16=0, IF(E16=0, 0, 100%), (E16 - D16) / D16) -> 0 | G16: =Orçamento!C13 -> 0 | H16: ='DRE 2026'!D13 -> 0 | I16: =IF(G16=0, IF(H16=0, 0, 100%), (H16 - G16) / G16) -> 0 | J16: =Orçamento!D13 -> 0 | K16: ='DRE 2026'!E13 -> 0 | L16: =IF(J16=0, IF(K16=0, 0, 100%), (K16 - J16) / J16) -> 0 | M16: =Orçamento!E13 -> 0 | N16: ='DRE 2026'!F13 -> 0 | O16: =IF(M16=0, IF(N16=0, 0, 100%), (N16 - M16) / M16) -> 0 | P16: =Orçamento!F13 -> 0 | Q16: ='DRE 2026'!G13 -> 0 | R16: =IF(P16=0, IF(Q16=0, 0, 100%), (Q16 - P16) / P16) -> 0 | S16: =Orçamento!G13 -> 0 | T16: ='DRE 2026'!H13 -> 0 | U16: =IF(S16=0, IF(T16=0, 0, 100%), (T16 - S16) / S16) -> 0 | V16: =Orçamento!H13 -> 0 | W16: ='DRE 2026'!I13 -> 0 | X16: =IF(V16=0, IF(W16=0, 0, 100%), (W16 - V16) / V16) -> 0 | Y16: =Orçamento!I13 -> 0 | Z16: ='DRE 2026'!J13 -> 0 | AA16: =IF(Y16=0, IF(Z16=0, 0, 100%), (Z16 - Y16) / Y16) -> 0 | AB16: =Orçamento!J13 -> 0 | AC16: ='DRE 2026'!K13 -> 0 | AD16: =IF(AB16=0, IF(AC16=0, 0, 100%), (AC16 - AB16) / AB16) -> 0 | AE16: =Orçamento!K13 -> 0 | AF16: ='DRE 2026'!L13 -> 0 | AG16: =IF(AE16=0, IF(AF16=0, 0, 100%), (AF16 - AE16) / AE16) -> 0 | AH16: =Orçamento!L13 -> 0 | AI16: ='DRE 2026'!M13 -> 0 | AJ16: =IF(AH16=0, IF(AI16=0, 0, 100%), (AI16 - AH16) / AH16) -> 0 | AK16: =Orçamento!M13 -> 0 | AL16: ='DRE 2026'!N13 -> 0 | AM16: =IF(AK16=0, IF(AL16=0, 0, 100%), (AL16 - AK16) / AK16) -> 0 | AO16: =IF(H16=0,D16,IF(K16=0,D16+G16,IF(N16=0,D16+G16+J16,IF(Q16=0,D16+G16+J16+M16,IF(T16=0,D16+G16+J16+M16+P16,D16+G16+J16+M16+P16+S16))))) -> 0 | AP16: =IF($H$7=0,E16,IF($K$7=0,E16+H16,IF($N$7=0,E16+H16+K16,IF($Q$7=0,E16+H16+K16+N16,IF($T$7=0,E16+H16+K16+N16+Q16,E16+H16+K16+N16+Q16+T16))))) -> 0 | AQ16: =IF(AO16=0, IF(AP16=0, 0, 100%), (AP16 - AO16) / AO16) -> 0 | AR16: =IF($Z$7=0,V16,IF($AC$7=0,V16+Y16,IF($AF$7=0,V16+Y16+AB16,IF($AI$7=0,V16+Y16+AB16+AE16,IF($AL$7=0,V16+Y16+AB16+AE16+AH16,V16+Y16+AB16+AE16+AH16+AK16))))) -> 0 | AS16: =IF($Z$7=0,W16,IF($AC$7=0,W16+Z16,IF($AF$7=0,W16+Z16+AC16,IF($AI$7=0,W16+Z16+AC16+AF16,IF($AL$7=0,W16+Z16+AC16+AF16+AI16,W16+Z16+AC16+AF16+AI16+AL16))))) -> 0 | AT16: =IF(AR16=0, IF(AS16=0, 0, 100%), (AS16 - AR16) / AR16) -> 0 | AU16: =AR16+AO16 -> 0 | AV16: =AP16+AS16 -> 0 | AW16: =IF(AU16=0, IF(AV16=0, 0, 100%), (AV16 - AU16) / AU16) -> 0
C17: Receita com Licença de Uso | D17: =Orçamento!B14 -> 0 | E17: ='DRE 2026'!C14 -> 0 | F17: =IF(D17=0, IF(E17=0, 0, 100%), (E17 - D17) / D17) -> 0 | G17: =Orçamento!C14 -> 0 | H17: ='DRE 2026'!D14 -> 0 | I17: =IF(G17=0, IF(H17=0, 0, 100%), (H17 - G17) / G17) -> 0 | J17: =Orçamento!D14 -> 0 | K17: ='DRE 2026'!E14 -> 0 | L17: =IF(J17=0, IF(K17=0, 0, 100%), (K17 - J17) / J17) -> 0 | M17: =Orçamento!E14 -> 0 | N17: ='DRE 2026'!F14 -> 0 | O17: =IF(M17=0, IF(N17=0, 0, 100%), (N17 - M17) / M17) -> 0 | P17: =Orçamento!F14 -> 0 | Q17: ='DRE 2026'!G14 -> 0 | R17: =IF(P17=0, IF(Q17=0, 0, 100%), (Q17 - P17) / P17) -> 0 | S17: =Orçamento!G14 -> 0 | T17: ='DRE 2026'!H14 -> 0 | U17: =IF(S17=0, IF(T17=0, 0, 100%), (T17 - S17) / S17) -> 0 | V17: =Orçamento!H14 -> 0 | W17: ='DRE 2026'!I14 -> 0 | X17: =IF(V17=0, IF(W17=0, 0, 100%), (W17 - V17) / V17) -> 0 | Y17: =Orçamento!I14 -> 0 | Z17: ='DRE 2026'!J14 -> 0 | AA17: =IF(Y17=0, IF(Z17=0, 0, 100%), (Z17 - Y17) / Y17) -> 0 | AB17: =Orçamento!J14 -> 0 | AC17: ='DRE 2026'!K14 -> 0 | AD17: =IF(AB17=0, IF(AC17=0, 0, 100%), (AC17 - AB17) / AB17) -> 0 | AE17: =Orçamento!K14 -> 0 | AF17: ='DRE 2026'!L14 -> 0 | AG17: =IF(AE17=0, IF(AF17=0, 0, 100%), (AF17 - AE17) / AE17) -> 0 | AH17: =Orçamento!L14 -> 0 | AI17: ='DRE 2026'!M14 -> 0 | AJ17: =IF(AH17=0, IF(AI17=0, 0, 100%), (AI17 - AH17) / AH17) -> 0 | AK17: =Orçamento!M14 -> 0 | AL17: ='DRE 2026'!N14 -> 0 | AM17: =IF(AK17=0, IF(AL17=0, 0, 100%), (AL17 - AK17) / AK17) -> 0 | AO17: =IF(H17=0,D17,IF(K17=0,D17+G17,IF(N17=0,D17+G17+J17,IF(Q17=0,D17+G17+J17+M17,IF(T17=0,D17+G17+J17+M17+P17,D17+G17+J17+M17+P17+S17))))) -> 0 | AP17: =IF($H$7=0,E17,IF($K$7=0,E17+H17,IF($N$7=0,E17+H17+K17,IF($Q$7=0,E17+H17+K17+N17,IF($T$7=0,E17+H17+K17+N17+Q17,E17+H17+K17+N17+Q17+T17))))) -> 0 | AQ17: =IF(AO17=0, IF(AP17=0, 0, 100%), (AP17 - AO17) / AO17) -> 0 | AR17: =IF($Z$7=0,V17,IF($AC$7=0,V17+Y17,IF($AF$7=0,V17+Y17+AB17,IF($AI$7=0,V17+Y17+AB17+AE17,IF($AL$7=0,V17+Y17+AB17+AE17+AH17,V17+Y17+AB17+AE17+AH17+AK17))))) -> 0 | AS17: =IF($Z$7=0,W17,IF($AC$7=0,W17+Z17,IF($AF$7=0,W17+Z17+AC17,IF($AI$7=0,W17+Z17+AC17+AF17,IF($AL$7=0,W17+Z17+AC17+AF17+AI17,W17+Z17+AC17+AF17+AI17+AL17))))) -> 0 | AT17: =IF(AR17=0, IF(AS17=0, 0, 100%), (AS17 - AR17) / AR17) -> 0 | AU17: =AR17+AO17 -> 0 | AV17: =AP17+AS17 -> 0 | AW17: =IF(AU17=0, IF(AV17=0, 0, 100%), (AV17 - AU17) / AU17) -> 0
C18: Receita com Vendas de QR Codes | D18: =Orçamento!B15 -> 0 | E18: ='DRE 2026'!C15 -> 100 | F18: =IF(D18=0, IF(E18=0, 0, 100%), (E18 - D18) / D18) -> 1 | G18: =Orçamento!C15 -> 0 | H18: ='DRE 2026'!D15 -> 240 | I18: =IF(G18=0, IF(H18=0, 0, 100%), (H18 - G18) / G18) -> 1 | J18: =Orçamento!D15 -> 0 | K18: ='DRE 2026'!E15 -> 305 | L18: =IF(J18=0, IF(K18=0, 0, 100%), (K18 - J18) / J18) -> 1 | M18: =Orçamento!E15 -> 0 | N18: ='DRE 2026'!F15 -> 285 | O18: =IF(M18=0, IF(N18=0, 0, 100%), (N18 - M18) / M18) -> 1 | P18: =Orçamento!F15 -> 0 | Q18: ='DRE 2026'!G15 -> 174 | R18: =IF(P18=0, IF(Q18=0, 0, 100%), (Q18 - P18) / P18) -> 1 | S18: =Orçamento!G15 -> 0 | T18: ='DRE 2026'!H15 -> 275 | U18: =IF(S18=0, IF(T18=0, 0, 100%), (T18 - S18) / S18) -> 1 | V18: =Orçamento!H15 -> 0 | W18: ='DRE 2026'!I15 -> 135 | X18: =IF(V18=0, IF(W18=0, 0, 100%), (W18 - V18) / V18) -> 1 | Y18: =Orçamento!I15 -> 0 | Z18: ='DRE 2026'!J15 -> 210 | AA18: =IF(Y18=0, IF(Z18=0, 0, 100%), (Z18 - Y18) / Y18) -> 1 | AB18: =Orçamento!J15 -> 0 | AC18: ='DRE 2026'!K15 -> 0 | AD18: =IF(AB18=0, IF(AC18=0, 0, 100%), (AC18 - AB18) / AB18) -> 0 | AE18: =Orçamento!K15 -> 0 | AF18: ='DRE 2026'!L15 -> 0 | AG18: =IF(AE18=0, IF(AF18=0, 0, 100%), (AF18 - AE18) / AE18) -> 0 | AH18: =Orçamento!L15 -> 0 | AI18: ='DRE 2026'!M15 -> 0 | AJ18: =IF(AH18=0, IF(AI18=0, 0, 100%), (AI18 - AH18) / AH18) -> 0 | AK18: =Orçamento!M15 -> 0 | AL18: ='DRE 2026'!N15 -> 0 | AM18: =IF(AK18=0, IF(AL18=0, 0, 100%), (AL18 - AK18) / AK18) -> 0 | AO18: =IF(H18=0,D18,IF(K18=0,D18+G18,IF(N18=0,D18+G18+J18,IF(Q18=0,D18+G18+J18+M18,IF(T18=0,D18+G18+J18+M18+P18,D18+G18+J18+M18+P18+S18))))) -> 0 | AP18: =IF($H$7=0,E18,IF($K$7=0,E18+H18,IF($N$7=0,E18+H18+K18,IF($Q$7=0,E18+H18+K18+N18,IF($T$7=0,E18+H18+K18+N18+Q18,E18+H18+K18+N18+Q18+T18))))) -> 1379 | AQ18: =IF(AO18=0, IF(AP18=0, 0, 100%), (AP18 - AO18) / AO18) -> 1 | AR18: =IF($Z$7=0,V18,IF($AC$7=0,V18+Y18,IF($AF$7=0,V18+Y18+AB18,IF($AI$7=0,V18+Y18+AB18+AE18,IF($AL$7=0,V18+Y18+AB18+AE18+AH18,V18+Y18+AB18+AE18+AH18+AK18))))) -> 0 | AS18: =IF($Z$7=0,W18,IF($AC$7=0,W18+Z18,IF($AF$7=0,W18+Z18+AC18,IF($AI$7=0,W18+Z18+AC18+AF18,IF($AL$7=0,W18+Z18+AC18+AF18+AI18,W18+Z18+AC18+AF18+AI18+AL18))))) -> 345 | AT18: =IF(AR18=0, IF(AS18=0, 0, 100%), (AS18 - AR18) / AR18) -> 1 | AU18: =AR18+AO18 -> 0 | AV18: =AP18+AS18 -> 1724 | AW18: =IF(AU18=0, IF(AV18=0, 0, 100%), (AV18 - AU18) / AU18) -> 1
C19: Deduções de Receita | D19: =Orçamento!B17 -> -39923.952 | E19: ='DRE 2026'!C16 -> -40017.8 | F19: =IF(D19=0, IF(E19=0, 0, 100%), (E19 - D19) / D19) -> 0.0023506687 | G19: =Orçamento!C17 -> -31524.092 | H19: ='DRE 2026'!D16 -> -39398.19 | I19: =IF(G19=0, IF(H19=0, 0, 100%), (H19 - G19) / G19) -> 0.24978033 | J19: =Orçamento!D17 -> -45607.451 | K19: ='DRE 2026'!E16 -> -27355.42 | L19: =IF(J19=0, IF(K19=0, 0, 100%), (K19 - J19) / J19) -> -0.40019844 | M19: =Orçamento!E17 -> -35173.806 | N19: ='DRE 2026'!F16 -> -36236.73 | O19: =IF(M19=0, IF(N19=0, 0, 100%), (N19 - M19) / M19) -> 0.03021919 | P19: =Orçamento!F17 -> -44293.662 | Q19: ='DRE 2026'!G16 -> -28528.1 | R19: =IF(P19=0, IF(Q19=0, 0, 100%), (Q19 - P19) / P19) -> -0.35593268 | S19: =Orçamento!G17 -> -36310.428 | T19: ='DRE 2026'!H16 -> -39028.04 | U19: =IF(S19=0, IF(T19=0, 0, 100%), (T19 - S19) / S19) -> 0.074843832 | V19: =Orçamento!H17 -> -47888.93 | W19: ='DRE 2026'!I16 -> -43587.67 | X19: =IF(V19=0, IF(W19=0, 0, 100%), (W19 - V19) / V19) -> -0.089817426 | Y19: =Orçamento!I17 -> -51482.375 | Z19: ='DRE 2026'!J16 -> -28063.11 | AA19: =IF(Y19=0, IF(Z19=0, 0, 100%), (Z19 - Y19) / Y19) -> -0.45489869 | AB19: =Orçamento!J17 -> -43783.786 | AC19: ='DRE 2026'!K16 -> 0 | AD19: =IF(AB19=0, IF(AC19=0, 0, 100%), (AC19 - AB19) / AB19) -> -1 | AE19: =Orçamento!K17 -> -41555.75 | AF19: ='DRE 2026'!L16 -> 0 | AG19: =IF(AE19=0, IF(AF19=0, 0, 100%), (AF19 - AE19) / AE19) -> -1 | AH19: =Orçamento!L17 -> -51494.002 | AI19: ='DRE 2026'!M16 -> 0 | AJ19: =IF(AH19=0, IF(AI19=0, 0, 100%), (AI19 - AH19) / AH19) -> -1 | AK19: =Orçamento!M17 -> -54327.966 | AL19: ='DRE 2026'!N16 -> 0 | AM19: =IF(AK19=0, IF(AL19=0, 0, 100%), (AL19 - AK19) / AK19) -> -1 | AO19: =IF(H19=0,D19,IF(K19=0,D19+G19,IF(N19=0,D19+G19+J19,IF(Q19=0,D19+G19+J19+M19,IF(T19=0,D19+G19+J19+M19+P19,D19+G19+J19+M19+P19+S19))))) -> -232833.39 | AP19: =IF($H$7=0,E19,IF($K$7=0,E19+H19,IF($N$7=0,E19+H19+K19,IF($Q$7=0,E19+H19+K19+N19,IF($T$7=0,E19+H19+K19+N19+Q19,E19+H19+K19+N19+Q19+T19))))) -> -210564.28 | AQ19: =IF(AO19=0, IF(AP19=0, 0, 100%), (AP19 - AO19) / AO19) -> -0.095643974 | AR19: =IF($Z$7=0,V19,IF($AC$7=0,V19+Y19,IF($AF$7=0,V19+Y19+AB19,IF($AI$7=0,V19+Y19+AB19+AE19,IF($AL$7=0,V19+Y19+AB19+AE19+AH19,V19+Y19+AB19+AE19+AH19+AK19))))) -> -99371.305 | AS19: =IF($Z$7=0,W19,IF($AC$7=0,W19+Z19,IF($AF$7=0,W19+Z19+AC19,IF($AI$7=0,W19+Z19+AC19+AF19,IF($AL$7=0,W19+Z19+AC19+AF19+AI19,W19+Z19+AC19+AF19+AI19+AL19))))) -> -71650.78 | AT19: =IF(AR19=0, IF(AS19=0, 0, 100%), (AS19 - AR19) / AR19) -> -0.27895905 | AU19: =AR19+AO19 -> -332204.7 | AV19: =AP19+AS19 -> -282215.06 | AW19: =IF(AU19=0, IF(AV19=0, 0, 100%), (AV19 - AU19) / AU19) -> -0.15047841
C20: Devoluções de Compra de Serviços (Chargeback) | D20: =Orçamento!B18 -> -3448.952 | E20: ='DRE 2026'!C17 -> -3999.96 | F20: =IF(D20=0, IF(E20=0, 0, 100%), (E20 - D20) / D20) -> 0.15976099 | G20: =Orçamento!C18 -> -2884.0919 | H20: ='DRE 2026'!D17 -> -6683.42 | I20: =IF(G20=0, IF(H20=0, 0, 100%), (H20 - G20) / G20) -> 1.3173395 | J20: =Orçamento!D18 -> -3855.4508 | K20: ='DRE 2026'!E17 -> -3125.48 | L20: =IF(J20=0, IF(K20=0, 0, 100%), (K20 - J20) / J20) -> -0.18933474 | M20: =Orçamento!E18 -> -3124.8061 | N20: ='DRE 2026'!F17 -> -6677 | O20: =IF(M20=0, IF(N20=0, 0, 100%), (N20 - M20) / M20) -> 1.1367726 | P20: =Orçamento!F18 -> -3965.6615 | Q20: ='DRE 2026'!G17 -> -4985.44 | R20: =IF(P20=0, IF(Q20=0, 0, 100%), (Q20 - P20) / P20) -> 0.25715218 | S20: =Orçamento!G18 -> -3356.4284 | T20: ='DRE 2026'!H17 -> -5484.14 | U20: =IF(S20=0, IF(T20=0, 0, 100%), (T20 - S20) / S20) -> 0.63392135 | V20: =Orçamento!H18 -> -4256.9305 | W20: ='DRE 2026'!I17 -> -14612.15 | X20: =IF(V20=0, IF(W20=0, 0, 100%), (W20 - V20) / V20) -> 2.4325555 | Y20: =Orçamento!I18 -> -4401.3747 | Z20: ='DRE 2026'!J17 -> -19866.11 | AA20: =IF(Y20=0, IF(Z20=0, 0, 100%), (Z20 - Y20) / Y20) -> 3.5136148 | AB20: =Orçamento!J18 -> -3682.7858 | AC20: ='DRE 2026'!K17 -> 0 | AD20: =IF(AB20=0, IF(AC20=0, 0, 100%), (AC20 - AB20) / AB20) -> -1 | AE20: =Orçamento!K18 -> -3531.7503 | AF20: ='DRE 2026'!L17 -> 0 | AG20: =IF(AE20=0, IF(AF20=0, 0, 100%), (AF20 - AE20) / AE20) -> -1 | AH20: =Orçamento!L18 -> -4101.0015 | AI20: ='DRE 2026'!M17 -> 0 | AJ20: =IF(AH20=0, IF(AI20=0, 0, 100%), (AI20 - AH20) / AH20) -> -1 | AK20: =Orçamento!M18 -> -4297.9662 | AL20: ='DRE 2026'!N17 -> 0 | AM20: =IF(AK20=0, IF(AL20=0, 0, 100%), (AL20 - AK20) / AK20) -> -1 | AO20: =IF(H20=0,D20,IF(K20=0,D20+G20,IF(N20=0,D20+G20+J20,IF(Q20=0,D20+G20+J20+M20,IF(T20=0,D20+G20+J20+M20+P20,D20+G20+J20+M20+P20+S20))))) -> -20635.391 | AP20: =IF($H$7=0,E20,IF($K$7=0,E20+H20,IF($N$7=0,E20+H20+K20,IF($Q$7=0,E20+H20+K20+N20,IF($T$7=0,E20+H20+K20+N20+Q20,E20+H20+K20+N20+Q20+T20))))) -> -30955.44 | AQ20: =IF(AO20=0, IF(AP20=0, 0, 100%), (AP20 - AO20) / AO20) -> 0.50011407 | AR20: =IF($Z$7=0,V20,IF($AC$7=0,V20+Y20,IF($AF$7=0,V20+Y20+AB20,IF($AI$7=0,V20+Y20+AB20+AE20,IF($AL$7=0,V20+Y20+AB20+AE20+AH20,V20+Y20+AB20+AE20+AH20+AK20))))) -> -8658.3052 | AS20: =IF($Z$7=0,W20,IF($AC$7=0,W20+Z20,IF($AF$7=0,W20+Z20+AC20,IF($AI$7=0,W20+Z20+AC20+AF20,IF($AL$7=0,W20+Z20+AC20+AF20+AI20,W20+Z20+AC20+AF20+AI20+AL20))))) -> -34478.26 | AT20: =IF(AR20=0, IF(AS20=0, 0, 100%), (AS20 - AR20) / AR20) -> 2.9821026 | AU20: =AR20+AO20 -> -29293.696 | AV20: =AP20+AS20 -> -65433.7 | AW20: =IF(AU20=0, IF(AV20=0, 0, 100%), (AV20 - AU20) / AU20) -> 1.2337127
C21: Devoluções de Compra (Estornos) | D21: =Orçamento!B19 -> 0 | E21: ='DRE 2026'!C18 -> -315 | F21: =IF(D21=0, IF(E21=0, 0, 100%), (E21 - D21) / D21) -> 1 | G21: =Orçamento!C19 -> 0 | H21: ='DRE 2026'!D18 -> 0 | I21: =IF(G21=0, IF(H21=0, 0, 100%), (H21 - G21) / G21) -> 0 | J21: =Orçamento!D19 -> 0 | K21: ='DRE 2026'!E18 -> 0 | L21: =IF(J21=0, IF(K21=0, 0, 100%), (K21 - J21) / J21) -> 0 | M21: =Orçamento!E19 -> 0 | N21: ='DRE 2026'!F18 -> 0 | O21: =IF(M21=0, IF(N21=0, 0, 100%), (N21 - M21) / M21) -> 0 | P21: =Orçamento!F19 -> 0 | Q21: ='DRE 2026'!G18 -> -368.6 | R21: =IF(P21=0, IF(Q21=0, 0, 100%), (Q21 - P21) / P21) -> 1 | S21: =Orçamento!G19 -> 0 | T21: ='DRE 2026'!H18 -> 0 | U21: =IF(S21=0, IF(T21=0, 0, 100%), (T21 - S21) / S21) -> 0 | V21: =Orçamento!H19 -> 0 | W21: ='DRE 2026'!I18 -> -380 | X21: =IF(V21=0, IF(W21=0, 0, 100%), (W21 - V21) / V21) -> 1 | Y21: =Orçamento!I19 -> 0 | Z21: ='DRE 2026'!J18 -> 0 | AA21: =IF(Y21=0, IF(Z21=0, 0, 100%), (Z21 - Y21) / Y21) -> 0 | AB21: =Orçamento!J19 -> 0 | AC21: ='DRE 2026'!K18 -> 0 | AD21: =IF(AB21=0, IF(AC21=0, 0, 100%), (AC21 - AB21) / AB21) -> 0 | AE21: =Orçamento!K19 -> 0 | AF21: ='DRE 2026'!L18 -> 0 | AG21: =IF(AE21=0, IF(AF21=0, 0, 100%), (AF21 - AE21) / AE21) -> 0 | AH21: =Orçamento!L19 -> 0 | AI21: ='DRE 2026'!M18 -> 0 | AJ21: =IF(AH21=0, IF(AI21=0, 0, 100%), (AI21 - AH21) / AH21) -> 0 | AK21: =Orçamento!M19 -> 0 | AL21: ='DRE 2026'!N18 -> 0 | AM21: =IF(AK21=0, IF(AL21=0, 0, 100%), (AL21 - AK21) / AK21) -> 0 | AO21: =IF(H21=0,D21,IF(K21=0,D21+G21,IF(N21=0,D21+G21+J21,IF(Q21=0,D21+G21+J21+M21,IF(T21=0,D21+G21+J21+M21+P21,D21+G21+J21+M21+P21+S21))))) -> 0 | AP21: =IF($H$7=0,E21,IF($K$7=0,E21+H21,IF($N$7=0,E21+H21+K21,IF($Q$7=0,E21+H21+K21+N21,IF($T$7=0,E21+H21+K21+N21+Q21,E21+H21+K21+N21+Q21+T21))))) -> -683.6 | AQ21: =IF(AO21=0, IF(AP21=0, 0, 100%), (AP21 - AO21) / AO21) -> 1 | AR21: =IF($Z$7=0,V21,IF($AC$7=0,V21+Y21,IF($AF$7=0,V21+Y21+AB21,IF($AI$7=0,V21+Y21+AB21+AE21,IF($AL$7=0,V21+Y21+AB21+AE21+AH21,V21+Y21+AB21+AE21+AH21+AK21))))) -> 0 | AS21: =IF($Z$7=0,W21,IF($AC$7=0,W21+Z21,IF($AF$7=0,W21+Z21+AC21,IF($AI$7=0,W21+Z21+AC21+AF21,IF($AL$7=0,W21+Z21+AC21+AF21+AI21,W21+Z21+AC21+AF21+AI21+AL21))))) -> -380 | AT21: =IF(AR21=0, IF(AS21=0, 0, 100%), (AS21 - AR21) / AR21) -> 1 | AU21: =AR21+AO21 -> 0 | AV21: =AP21+AS21 -> -1063.6 | AW21: =IF(AU21=0, IF(AV21=0, 0, 100%), (AV21 - AU21) / AU21) -> 1
C22: Simples Nacional (DAS) | D22: =Orçamento!B20 -> -36475 | E22: ='DRE 2026'!C19 -> -35702.84 | F22: =IF(D22=0, IF(E22=0, 0, 100%), (E22 - D22) / D22) -> -0.021169568 | G22: =Orçamento!C20 -> -28640 | H22: ='DRE 2026'!D19 -> -32714.77 | I22: =IF(G22=0, IF(H22=0, 0, 100%), (H22 - G22) / G22) -> 0.14227549 | J22: =Orçamento!D20 -> -41752 | K22: ='DRE 2026'!E19 -> -24229.94 | L22: =IF(J22=0, IF(K22=0, 0, 100%), (K22 - J22) / J22) -> -0.41966996 | M22: =Orçamento!E20 -> -32049 | N22: ='DRE 2026'!F19 -> -29559.73 | O22: =IF(M22=0, IF(N22=0, 0, 100%), (N22 - M22) / M22) -> -0.077670754 | P22: =Orçamento!F20 -> -40328 | Q22: ='DRE 2026'!G19 -> -23174.06 | R22: =IF(P22=0, IF(Q22=0, 0, 100%), (Q22 - P22) / P22) -> -0.42536054 | S22: =Orçamento!G20 -> -32954 | T22: ='DRE 2026'!H19 -> -33543.9 | U22: =IF(S22=0, IF(T22=0, 0, 100%), (T22 - S22) / S22) -> 0.01790071 | V22: =Orçamento!H20 -> -43632 | W22: ='DRE 2026'!I19 -> -28595.52 | X22: =IF(V22=0, IF(W22=0, 0, 100%), (W22 - V22) / V22) -> -0.34462046 | Y22: =Orçamento!I20 -> -47081 | Z22: ='DRE 2026'!J19 -> -8197 | AA22: =IF(Y22=0, IF(Z22=0, 0, 100%), (Z22 - Y22) / Y22) -> -0.8258958 | AB22: =Orçamento!J20 -> -40101 | AC22: ='DRE 2026'!K19 -> 0 | AD22: =IF(AB22=0, IF(AC22=0, 0, 100%), (AC22 - AB22) / AB22) -> -1 | AE22: =Orçamento!K20 -> -38024 | AF22: ='DRE 2026'!L19 -> 0 | AG22: =IF(AE22=0, IF(AF22=0, 0, 100%), (AF22 - AE22) / AE22) -> -1 | AH22: =Orçamento!L20 -> -47393 | AI22: ='DRE 2026'!M19 -> 0 | AJ22: =IF(AH22=0, IF(AI22=0, 0, 100%), (AI22 - AH22) / AH22) -> -1 | AK22: =Orçamento!M20 -> -50030 | AL22: ='DRE 2026'!N19 -> 0 | AM22: =IF(AK22=0, IF(AL22=0, 0, 100%), (AL22 - AK22) / AK22) -> -1 | AO22: =IF(H22=0,D22,IF(K22=0,D22+G22,IF(N22=0,D22+G22+J22,IF(Q22=0,D22+G22+J22+M22,IF(T22=0,D22+G22+J22+M22+P22,D22+G22+J22+M22+P22+S22))))) -> -212198 | AP22: =IF($H$7=0,E22,IF($K$7=0,E22+H22,IF($N$7=0,E22+H22+K22,IF($Q$7=0,E22+H22+K22+N22,IF($T$7=0,E22+H22+K22+N22+Q22,E22+H22+K22+N22+Q22+T22))))) -> -178925.24 | AQ22: =IF(AO22=0, IF(AP22=0, 0, 100%), (AP22 - AO22) / AO22) -> -0.15680054 | AR22: =IF($Z$7=0,V22,IF($AC$7=0,V22+Y22,IF($AF$7=0,V22+Y22+AB22,IF($AI$7=0,V22+Y22+AB22+AE22,IF($AL$7=0,V22+Y22+AB22+AE22+AH22,V22+Y22+AB22+AE22+AH22+AK22))))) -> -90713 | AS22: =IF($Z$7=0,W22,IF($AC$7=0,W22+Z22,IF($AF$7=0,W22+Z22+AC22,IF($AI$7=0,W22+Z22+AC22+AF22,IF($AL$7=0,W22+Z22+AC22+AF22+AI22,W22+Z22+AC22+AF22+AI22+AL22))))) -> -36792.52 | AT22: =IF(AR22=0, IF(AS22=0, 0, 100%), (AS22 - AR22) / AR22) -> -0.59440742 | AU22: =AR22+AO22 -> -302911 | AV22: =AP22+AS22 -> -215717.76 | AW22: =IF(AU22=0, IF(AV22=0, 0, 100%), (AV22 - AU22) / AU22) -> -0.28785102
