Workbook

Sheet Resultados
F2: janeiro | G2: fevereiro | H2: março | I2: abril | J2: maio | K2: junho | L2: julho | M2: agosto | N2: setembro | O2: outubro | P2: novembro | Q2: dezembro | R2: 2026 | T2: 1 SEM | U2: 2 SEM | V2: 2024
B4: Receita Operacional Bruta | F4: =F5+F8+F11+F14+F15+F16+F17+F21+F22+F23 -> 1686702.6 | G4: =G5+G8+G11+G14+G15+G16+G17+G21+G22+G23 -> 1279880.2 | H4: =H5+H8+H11+H14+H15+H16+H17+H21+H22+H23 -> 1452060.6 | I4: =I5+I8+I11+I14+I15+I16+I17+I21+I22+I23 -> 1422561.5 | J4: =J5+J8+J11+J14+J15+J16+J17+J21+J22+J23 -> 1596280.6 | K4: =K5+K8+K11+K14+K15+K16+K17+K21+K22+K23 -> 1566052 | L4: =L5+L8+L11+L14+L15+L16+L17+L21+L22+L23 -> 1647475.2 | M4: =M5+M8+M11+M14+M15+M16+M17+M21+M22+M23 -> 1388629.3 | ... R4: =R5+R8+R11+R14+R15+R16+R17+R21+R22+R23 -> 12039642 | T4: =SUM(F4:K4) -> 9003537.4 | U4: =SUM(L4:Q4) -> 3036104.5 | V4: =T4+U4 -> 12039642
C5: Royalties | F5: =SUM(F6:F7) -> 858569.87 | G5: =SUM(G6:G7) -> 598623.74 | H5: =SUM(H6:H7) -> 606841.34 | I5: =SUM(I6:I7) -> 632427.22 | J5: =SUM(J6:J7) -> 530748.99 | K5: =SUM(K6:K7) -> 750091.11 | L5: =SUM(L6:L7) -> 765899.31 | M5: =SUM(M6:M7) -> 606346.88 | ... R5: =SUM(R6:R7) -> 5349548.5 | T5: =SUM(F5:K5) -> 3977302.3 | U5: =SUM(L5:Q5) -> 1372246.2 | V5: =T5+U5 -> 5349548.5
D6: Royalties - Recorrentes | F6: ='Cálculos de Impostos'!F6 -> 742596.16 | G6: ='Cálculos de Impostos'!G6 -> 520688.71 | H6: ='Cálculos de Impostos'!H6 -> 578703 | I6: ='Cálculos de Impostos'!I6 -> 609147.54 | J6: ='Cálculos de Impostos'!J6 -> 518335.49 | K6: ='Cálculos de Impostos'!K6 -> 638364.5 | L6: ='Cálculos de Impostos'!L6 -> 678311.33 | M6: ='Cálculos de Impostos'!M6 -> 534530.06 | ... Q6: ='Cálculos de Impostos'!Q6 -> 0 | R6: =SUM(F6:Q6) -> 4820676.8 | T6: =SUM(F6:K6) -> 3607835.4 | U6: =SUM(L6:Q6) -> 1212841.4 | V6: =T6+U6 -> 4820676.8
D7: Royalties - Fechamentos | F7: ='Cálculos de Impostos'!F7 -> 115973.71 | G7: ='Cálculos de Impostos'!G7 -> 77935.03 | H7: ='Cálculos de Impostos'!H7 -> 28138.34 | I7: ='Cálculos de Impostos'!I7 -> 23279.68 | J7: ='Cálculos de Impostos'!J7 -> 12413.5 | K7: ='Cálculos de Impostos'!K7 -> 111726.61 | L7: ='Cálculos de Impostos'!L7 -> 87587.98 | M7: ='Cálculos de Impostos'!M7 -> 71816.82 | ... Q7: ='Cálculos de Impostos'!Q7 -> 0 | R7: =SUM(F7:Q7) -> 528871.67 | T7: =SUM(F7:K7) -> 369466.87 | U7: =SUM(L7:Q7) -> 159404.8 | V7: =T7+U7 -> 528871.67
C8: Fundo de Marketing | F8: =SUM(F9:F10) -> 53494.86 | G8: =SUM(G9:G10) -> 36027.51 | H8: =SUM(H9:H10) -> 40270.14 | I8: =SUM(I9:I10) -> 37264.5 | J8: =SUM(J9:J10) -> 36951.48 | K8: =SUM(K9:K10) -> 46118.45 | L8: =SUM(L9:L10) -> 45244.39 | M8: =SUM(M9:M10) -> 38702.04 | ... R8: =SUM(R9:R10) -> 334073.37 | T8: =SUM(F8:K8) -> 250126.94 | U8: =SUM(L8:Q8) -> 83946.43 | V8: =T8+U8 -> 334073.37
D9: Fundo de Marketing - Recorrentes | F9: ='Cálculos de Impostos'!F9 -> 46209.41 | G9: ='Cálculos de Impostos'!G9 -> 30939.14 | H9: ='Cálculos de Impostos'!H9 -> 38474.08 | I9: ='Cálculos de Impostos'!I9 -> 35766.61 | J9: ='Cálculos de Impostos'!J9 -> 32874.72 | K9: ='Cálculos de Impostos'!K9 -> 44826.72 | L9: ='Cálculos de Impostos'!L9 -> 43952.66 | M9: ='Cálculos de Impostos'!M9 -> 36368.87 | ... Q9: ='Cálculos de Impostos'!Q9 -> 0 | R9: =SUM(F9:Q9) -> 309412.21 | T9: =SUM(F9:K9) -> 229090.68 | U9: =SUM(L9:Q9) -> 80321.53 | V9: =T9+U9 -> 309412.21
D10: Fundo de Marketing - Fechamentos | F10: ='Cálculos de Impostos'!F10 -> 7285.45 | G10: ='Cálculos de Impostos'!G10 -> 5088.37 | H10: ='Cálculos de Impostos'!H10 -> 1796.06 | I10: ='Cálculos de Impostos'!I10 -> 1497.89 | J10: ='Cálculos de Impostos'!J10 -> 4076.76 | K10: ='Cálculos de Impostos'!K10 -> 1291.73 | L10: ='Cálculos de Impostos'!L10 -> 1291.73 | M10: ='Cálculos de Impostos'!M10 -> 2333.17 | ... Q10: ='Cálculos de Impostos'!Q10 -> 0 | R10: =SUM(F10:Q10) -> 24661.16 | T10: =SUM(F10:K10) -> 21036.26 | U10: =SUM(L10:Q10) -> 3624.9 | V10: =T10+U10 -> 24661.16
C11: Taxas de Franquias | F11: =F12+F13 -> 0 | G11: =G12+G13 -> 0 | H11: =H12+H13 -> 0 | I11: =I12+I13 -> 0 | J11: =J12+J13 -> 0 | K11: =K12+K13 -> 0 | L11: =L12+L13 -> 0 | M11: =M12+M13 -> 0 | ... R11: =R12+R13 -> 0 | T11: =SUM(F11:K11) -> 0 | U11: =SUM(L11:Q11) -> 0 | V11: =T11+U11 -> 0
D12: Taxa Inicial de Franquia | F12: ='Cálculos de Impostos'!F12 -> 0 | G12: ='Cálculos de Impostos'!G12 -> 0 | H12: ='Cálculos de Impostos'!H12 -> 0 | I12: ='Cálculos de Impostos'!I12 -> 0 | J12: ='Cálculos de Impostos'!J12 -> 0 | K12: ='Cálculos de Impostos'!K12 -> 0 | L12: ='Cálculos de Impostos'!L12 -> 0 | M12: ='Cálculos de Impostos'!M12 -> 0 | ... Q12: ='Cálculos de Impostos'!Q12 -> 0 | R12: =SUM(F12:Q12) -> 0 | T12: =SUM(F12:K12) -> 0 | U12: =SUM(L12:Q12) -> 0 | V12: =T12+U12 -> 0
D13: Renovação de Franquias | F13: ='Cálculos de Impostos'!F13 -> 0 | G13: ='Cálculos de Impostos'!G13 -> 0 | H13: ='Cálculos de Impostos'!H13 -> 0 | I13: ='Cálculos de Impostos'!I13 -> 0 | J13: ='Cálculos de Impostos'!J13 -> 0 | K13: ='Cálculos de Impostos'!K13 -> 0 | L13: ='Cálculos de Impostos'!L13 -> 0 | M13: ='Cálculos de Impostos'!M13 -> 0 | ... Q13: ='Cálculos de Impostos'!Q13 -> 0 | R13: =SUM(F13:Q13) -> 0 | T13: =SUM(F13:K13) -> 0 | U13: =SUM(L13:Q13) -> 0 | V13: =T13+U13 -> 0
C14: Receita com Patrocínios | F14: ='Cálculos de Impostos'!F14 -> 0 | G14: ='Cálculos de Impostos'!G14 -> 0 | H14: ='Cálculos de Impostos'!H14 -> 0 | I14: ='Cálculos de Impostos'!I14 -> 0 | J14: ='Cálculos de Impostos'!J14 -> 0 | K14: ='Cálculos de Impostos'!K14 -> 0 | L14: ='Cálculos de Impostos'!L14 -> 0 | M14: ='Cálculos de Impostos'!M14 -> 0 | ... Q14: ='Cálculos de Impostos'!Q14 -> 0 | R14: =SUM(F14:Q14) -> 0 | T14: =SUM(F14:K14) -> 0 | U14: =SUM(L14:Q14) -> 0 | V14: =T14+U14 -> 0
C15: Receita SPDX | F15: ='Cálculos de Impostos'!F15 -> 435100.22 | G15: ='Cálculos de Impostos'!G15 -> 385150.49 | H15: ='Cálculos de Impostos'!H15 -> 538232.09 | I15: ='Cálculos de Impostos'!I15 -> 487174.31 | J15: ='Cálculos de Impostos'!J15 -> 486610.35 | K15: ='Cálculos de Impostos'!K15 -> 486259.18 | L15: ='Cálculos de Impostos'!L15 -> 517608.2 | M15: ='Cálculos de Impostos'!M15 -> 467285.15 | ... Q15: ='Cálculos de Impostos'!Q15 -> 0 | R15: =SUM(F15:Q15) -> 3803420 | T15: =SUM(F15:K15) -> 2818526.6 | U15: =SUM(L15:Q15) -> 984893.35 | V15: =T15+U15 -> 3803420
C16: Receitas - Taxa Mundo Viva | F16: ='Cálculos de Impostos'!F16 -> 76119.7 | G16: ='Cálculos de Impostos'!G16 -> 73017 | H16: ='Cálculos de Impostos'!H16 -> 71232.9 | I16: ='Cálculos de Impostos'!I16 -> 70336.1 | J16: ='Cálculos de Impostos'!J16 -> 73790.3 | K16: ='Cálculos de Impostos'!K16 -> 73663 | L16: ='Cálculos de Impostos'!L16 -> 76239.4 | M16: ='Cálculos de Impostos'!M16 -> 77537.1 | ... Q16: ='Cálculos de Impostos'!Q16 -> 0 | R16: =SUM(F16:Q16) -> 591935.5 | T16: =SUM(F16:K16) -> 438159 | U16: =SUM(L16:Q16) -> 153776.5 | V16: =T16+U16 -> 591935.5
C17: Receitas - Markup de Tarifas | F17: =F18+F19+F20 -> 175537.31 | G17: =G18+G19+G20 -> 105459.15 | H17: =H18+H19+H20 -> 115377.65 | I17: =I18+I19+I20 -> 107690.23 | J17: =J18+J19+J20 -> 125373.64 | K17: =K18+K19+K20 -> 130235.64 | L17: =L18+L19+L20 -> 159580.33 | M17: =M18+M19+M20 -> 110404.67 | ... R17: =R18+R19+R20 -> 1029658.6 | T17: =SUM(F17:K17) -> 759673.62 | U17: =SUM(L17:Q17) -> 269985 | V17: =T17+U17 -> 1029658.6
D18: Markup de Liquidação de boletos | F18: ='Cálculos de Impostos'!F18 -> 33721.79 | G18: ='Cálculos de Impostos'!G18 -> 29503.82 | H18: ='Cálculos de Impostos'!H18 -> 37861.57 | I18: ='Cálculos de Impostos'!I18 -> 31977.18 | J18: ='Cálculos de Impostos'!J18 -> 32255.93 | K18: ='Cálculos de Impostos'!K18 -> 37591.02 | L18: ='Cálculos de Impostos'!L18 -> 39603.36 | M18: ='Cálculos de Impostos'!M18 -> 36696.37 | ... Q18: ='Cálculos de Impostos'!Q18 -> 0 | R18: =SUM(F18:Q18) -> 279211.04 | T18: =SUM(F18:K18) -> 202911.31 | U18: =SUM(L18:Q18) -> 76299.73 | V18: =T18+U18 -> 279211.04
D19: Markup de cartão | F19: ='Cálculos de Impostos'!F19 -> 138056.49 | G19: ='Cálculos de Impostos'!G19 -> 72990.74 | H19: ='Cálculos de Impostos'!H19 -> 73001.08 | I19: ='Cálculos de Impostos'!I19 -> 73181.66 | J19: ='Cálculos de Impostos'!J19 -> 90920.72 | K19: ='Cálculos de Impostos'!K19 -> 89856.48 | L19: ='Cálculos de Impostos'!L19 -> 116286.7 | M19: ='Cálculos de Impostos'!M19 -> 70079.12 | ... Q19: ='Cálculos de Impostos'!Q19 -> 0 | R19: =SUM(F19:Q19) -> 724372.99 | T19: =SUM(F19:K19) -> 538007.17 | U19: =SUM(L19:Q19) -> 186365.82 | V19: =T19+U19 -> 724372.99
D20: Markup de tarifas bancárias | F20: ='Cálculos de Impostos'!F20 -> 3759.03 | G20: ='Cálculos de Impostos'!G20 -> 2964.59 | H20: ='Cálculos de Impostos'!H20 -> 4515 | I20: ='Cálculos de Impostos'!I20 -> 2531.39 | J20: ='Cálculos de Impostos'!J20 -> 2196.99 | K20: ='Cálculos de Impostos'!K20 -> 2788.14 | L20: ='Cálculos de Impostos'!L20 -> 3690.27 | M20: ='Cálculos de Impostos'!M20 -> 3629.18 | ... Q20: ='Cálculos de Impostos'!Q20 -> 0 | R20: =SUM(F20:Q20) -> 26074.59 | T20: =SUM(F20:K20) -> 18755.14 | U20: =SUM(L20:Q20) -> 7319.45 | V20: =T20+U20 -> 26074.59
C21: Receitas - Festas de Arrecadação | F21: ='Cálculos de Impostos'!F21 -> 3762.29 | G21: ='Cálculos de Impostos'!G21 -> 6307.8 | H21: ='Cálculos de Impostos'!H21 -> 6771.63 | I21: ='Cálculos de Impostos'!I21 -> 7115.56 | J21: ='Cálculos de Impostos'!J21 -> 263540.41 | K21: ='Cálculos de Impostos'!K21 -> 12085.48 | L21: ='Cálculos de Impostos'!L21 -> 9083.4 | M21: ='Cálculos de Impostos'!M21 -> 10163.01 | ... Q21: ='Cálculos de Impostos'!Q21 -> 0 | R21: =SUM(F21:Q21) -> 318829.58 | T21: =SUM(F21:K21) -> 299583.17 | U21: =SUM(L21:Q21) -> 19246.41 | V21: =T21+U21 -> 318829.58
C22: Receita com Projetos | F22: ='Cálculos de Impostos'!F22 -> 1640.5782 | G22: ='Cálculos de Impostos'!G22 -> 1146.6088 | H22: ='Cálculos de Impostos'!H22 -> 1200.1852 | I22: ='Cálculos de Impostos'!I22 -> 220.52859 | J22: ='Cálculos de Impostos'!J22 -> 146.8843 | K22: ='Cálculos de Impostos'!K22 -> 984.60246 | L22: ='Cálculos de Impostos'!L22 -> 2093.0596 | M22: ='Cálculos de Impostos'!M22 -> 1140.343 | ... Q22: ='Cálculos de Impostos'!Q22 -> 0 | R22: =SUM(F22:Q22) -> 8572.7901 | T22: =SUM(F22:K22) -> 5339.3876 | U22: =SUM(L22:Q22) -> 3233.4026 | V22: =T22+U22 -> 8572.7901
C23: Receitas - Assessoria CSC | F23: =F24+F25+F26 -> 82477.8 | G23: =G24+G25+G26 -> 74147.94 | H23: =H24+H25+H26 -> 72134.63 | I23: =I24+I25+I26 -> 80333.03 | J23: =J24+J25+J26 -> 79118.51 | K23: =K24+K25+K26 -> 66614.5 | L23: =L24+L25+L26 -> 71727.16 | M23: =M24+M25+M26 -> 77050.1 | ... R23: =R24+R25+R26 -> 603603.67 | T23: =SUM(F23:K23) -> 454826.41 | U23: =SUM(L23:Q23) -> 148777.26 | V23: =T23+U23 -> 603603.67
D24: Assessoria CSC - Quokka | F24: ='Cálculos de Impostos'!F24 -> 49703 | G24: ='Cálculos de Impostos'!G24 -> 46767 | H24: ='Cálculos de Impostos'!H24 -> 41835.5 | I24: ='Cálculos de Impostos'!I24 -> 41835.5 | J24: ='Cálculos de Impostos'!J24 -> 45335.5 | K24: ='Cálculos de Impostos'!K24 -> 40214.5 | L24: ='Cálculos de Impostos'!L24 -> 39404 | M24: ='Cálculos de Impostos'!M24 -> 37783 | ... Q24: ='Cálculos de Impostos'!Q24 -> 0 | R24: =SUM(F24:Q24) -> 342878 | T24: =SUM(F24:K24) -> 265691 | U24: =SUM(L24:Q24) -> 77187 | V24: =T24+U24 -> 342878
D25: Assessoria Central de Talentos | F25: ='Cálculos de Impostos'!F25 -> 3774.8 | G25: ='Cálculos de Impostos'!G25 -> 3380.94 | H25: ='Cálculos de Impostos'!H25 -> 5299.13 | I25: ='Cálculos de Impostos'!I25 -> 12245.03 | J25: ='Cálculos de Impostos'!J25 -> 4283.01 | K25: ='Cálculos de Impostos'!K25 -> 0 | L25: ='Cálculos de Impostos'!L25 -> 3023.16 | M25: ='Cálculos de Impostos'!M25 -> 4967.1 | ... Q25: ='Cálculos de Impostos'!Q25 -> 0 | R25: =SUM(F25:Q25) -> 36973.17 | T25: =SUM(F25:K25) -> 28982.91 | U25: =SUM(L25:Q25) -> 7990.26 | V25: =T25+U25 -> 36973.17
D26: Assessoria CSC - Atendimento | F26: ='Cálculos de Impostos'!F26 -> 29000 | G26: ='Cálculos de Impostos'!G26 -> 24000 | H26: ='Cálculos de Impostos'!H26 -> 25000 | I26: ='Cálculos de Impostos'!I26 -> 26252.5 | J26: ='Cálculos de Impostos'!J26 -> 29500 | K26: ='Cálculos de Impostos'!K26 -> 26400 | L26: ='Cálculos de Impostos'!L26 -> 29300 | M26: ='Cálculos de Impostos'!M26 -> 34300 | ... Q26: ='Cálculos de Impostos'!Q26 -> 0 | R26: =SUM(F26:Q26) -> 223752.5 | T26: =SUM(F26:K26) -> 160152.5 | U26: =SUM(L26:Q26) -> 63600 | V26: =T26+U26 -> 223752.5
B27: Deduções de Receita | F27: =F28+F29+F33+F37 -> -104494.82 | G27: =G28+G29+G33+G37 -> -75622.536 | H27: =H28+H29+H33+H37 -> -80727.962 | I27: =I28+I29+I33+I37 -> -78716.017 | J27: =J28+J29+J33+J37 -> -74576.061 | K27: =K28+K29+K33+K37 -> -187978.64 | L27: =L28+L29+L33+L37 -> -75289.378 | M27: =M28+M29+M33+M37 -> -61021.424 | ... Q27: =Q28+Q29+Q33+Q37 -> 0 | R27: =SUM(F27:Q27) -> -738426.84 | T27: =SUM(F27:K27) -> -602116.04 | U27: =SUM(L27:Q27) -> -136310.8 | V27: =T27+U27 -> -738426.84
C28: Devoluções de Vendas de Serviços Prestados | F28: ='Cálculos de Impostos'!F28 -> -19.64 | G28: ='Cálculos de Impostos'!G28 -> -1292.74 | H28: ='Cálculos de Impostos'!H28 -> -4648.39 | I28: ='Cálculos de Impostos'!I28 -> -526.91 | J28: ='Cálculos de Impostos'!J28 -> 0 | K28: ='Cálculos de Impostos'!K28 -> -120275.68 | L28: ='Cálculos de Impostos'!L28 -> 0 | M28: ='Cálculos de Impostos'!M28 -> -2177.59 | ... Q28: ='Cálculos de Impostos'!Q28 -> 0 | R28: =SUM(F28:Q28) -> -128940.95 | T28: =SUM(F28:K28) -> -126763.36 | U28: =SUM(L28:Q28) -> -2177.59 | V28: =T28+U28 -> -128940.95
C29: PIS | F29: =F30+F31+F32 -> -7418.9965 | G29: =G30+G31+G32 -> -5264.8179 | H29: =H30+H31+H32 -> -5383.3907 | I29: =I30+I31+I32 -> -5540.4929 | J29: =J30+J31+J32 -> -6046.1741 | K29: =K30+K31+K32 -> -6415.9908 | L29: =L30+L31+L32 -> -6732.5094 | M29: =M30+M31+M32 -> -5410.7675 | ... R29: =R30+R31+R32 -> -48213.14 | T29: =SUM(F29:K29) -> -36069.863 | U29: =SUM(L29:Q29) -> -12143.277 | V29: =T29+U29 -> -48213.14
D30: PIS - V E | F30: ='Cálculos de Impostos'!F30 -> -6029.7188 | G30: ='Cálculos de Impostos'!G30 -> -4217.776 | H30: ='Cálculos de Impostos'!H30 -> -4298.4151 | I30: ='Cálculos de Impostos'!I30 -> -4451.9056 | J30: ='Cálculos de Impostos'!J30 -> -3775.9162 | K30: ='Cálculos de Impostos'!K30 -> -5232.0488 | L30: ='Cálculos de Impostos'!L30 -> -5385.7768 | M30: ='Cálculos de Impostos'!M30 -> -4268.6898 | ... Q30: ='Cálculos de Impostos'!Q30 -> 0 | R30: =SUM(F30:Q30) -> -37660.247 | T30: =SUM(F30:K30) -> -28005.78 | U30: =SUM(L30:Q30) -> -9654.4666 | V30: =T30+U30 -> -37660.247
D31: PIS - SPDX | F31: ='Cálculos de Impostos'!F31 -> -282.76946 | G31: ='Cálculos de Impostos'!G31 -> -271.67581 | H31: ='Cálculos de Impostos'!H31 -> -265.45937 | I31: ='Cálculos de Impostos'!I31 -> -262.53371 | J31: ='Cálculos de Impostos'!J31 -> -276.3004 | K31: ='Cálculos de Impostos'!K31 -> -276.47786 | L31: ='Cálculos de Impostos'!L31 -> -284.34247 | M31: ='Cálculos de Impostos'!M31 -> -291.70698 | ... Q31: ='Cálculos de Impostos'!Q31 -> 0 | R31: =SUM(F31:Q31) -> -2211.2661 | T31: =SUM(F31:K31) -> -1635.2166 | U31: =SUM(L31:Q31) -> -576.04944 | V31: =T31+U31 -> -2211.2661
D32: PIS - Dataforte | F32: ='Cálculos de Impostos'!F32 -> -1106.5083 | G32: ='Cálculos de Impostos'!G32 -> -775.36617 | H32: ='Cálculos de Impostos'!H32 -> -819.51624 | I32: ='Cálculos de Impostos'!I32 -> -826.05356 | J32: ='Cálculos de Impostos'!J32 -> -1993.9575 | K32: ='Cálculos de Impostos'!K32 -> -907.46413 | L32: ='Cálculos de Impostos'!L32 -> -1062.3901 | M32: ='Cálculos de Impostos'!M32 -> -850.37073 | ... Q32: ='Cálculos de Impostos'!Q32 -> 0 | R32: =SUM(F32:Q32) -> -8341.6267 | T32: =SUM(F32:K32) -> -6428.8659 | U32: =SUM(L32:Q32) -> -1912.7608 | V32: =T32+U32 -> -8341.6267
C33: COFINS | F33: =F34+F35+F36 -> -34235.178 | G33: =G34+G35+G36 -> -24294.179 | H33: =H34+H35+H36 -> -24841.312 | I33: =I34+I35+I36 -> -25566.395 | J33: =J34+J35+J36 -> -27895.684 | K33: =K34+K35+K36 -> -29606.738 | L33: =L34+L35+L36 -> -31066.936 | M33: =M34+M35+M36 -> -24967.356 | ... R33: =R34+R35+R36 -> -222473.78 | T33: =SUM(F33:K33) -> -166439.49 | U33: =SUM(L33:Q33) -> -56034.292 | V33: =T33+U33 -> -222473.78
D34: COFINS - V E | F34: ='Cálculos de Impostos'!F34 -> -27829.471 | G34: ='Cálculos de Impostos'!G34 -> -19466.658 | H34: ='Cálculos de Impostos'!H34 -> -19838.839 | I34: ='Cálculos de Impostos'!I34 -> -20547.256 | J34: ='Cálculos de Impostos'!J34 -> -17427.305 | K34: ='Cálculos de Impostos'!K34 -> -24147.918 | L34: ='Cálculos de Impostos'!L34 -> -24857.431 | M34: ='Cálculos de Impostos'!M34 -> -19701.645 | ... Q34: ='Cálculos de Impostos'!Q34 -> 0 | R34: =SUM(F34:Q34) -> -173816.52 | T34: =SUM(F34:K34) -> -129257.45 | U34: =SUM(L34:Q34) -> -44559.077 | V34: =T34+U34 -> -173816.52
D35: COFINS - SPDX | F35: ='Cálculos de Impostos'!F35 -> -1303.0322 | G35: ='Cálculos de Impostos'!G35 -> -1251.9115 | H35: ='Cálculos de Impostos'!H35 -> -1223.2655 | I35: ='Cálculos de Impostos'!I35 -> -1209.7837 | J35: ='Cálculos de Impostos'!J35 -> -1273.2221 | K35: ='Cálculos de Impostos'!K35 -> -1274.0399 | L35: ='Cálculos de Impostos'!L35 -> -1310.2808 | M35: ='Cálculos de Impostos'!M35 -> -1344.2173 | ... Q35: ='Cálculos de Impostos'!Q35 -> 0 | R35: =SUM(F35:Q35) -> -10189.753 | T35: =SUM(F35:K35) -> -7535.255 | U35: =SUM(L35:Q35) -> -2654.4981 | V35: =T35+U35 -> -10189.753
D36: COFINS - Dataforte | F36: ='Cálculos de Impostos'!F36 -> -5102.6749 | G36: ='Cálculos de Impostos'!G36 -> -3575.6095 | H36: ='Cálculos de Impostos'!H36 -> -3779.208 | I36: ='Cálculos de Impostos'!I36 -> -3809.3549 | J36: ='Cálculos de Impostos'!J36 -> -9195.1566 | K36: ='Cálculos de Impostos'!K36 -> -4184.7806 | L36: ='Cálculos de Impostos'!L36 -> -4899.2233 | M36: ='Cálculos de Impostos'!M36 -> -3921.4938 | ... Q36: ='Cálculos de Impostos'!Q36 -> 0 | R36: =SUM(F36:Q36) -> -38467.502 | T36: =SUM(F36:K36) -> -29646.785 | U36: =SUM(L36:Q36) -> -8820.7171 | V36: =T36+U36 -> -38467.502
C37: ISS | F37: =F38+F39+F40 -> -62821.007 | G37: =G38+G39+G40 -> -44770.799 | H37: =H38+H39+H40 -> -45854.869 | I37: =I38+I39+I40 -> -47082.219 | J37: =J38+J39+J40 -> -40634.203 | K37: =K38+K39+K40 -> -31680.229 | L37: =L38+L39+L40 -> -37489.933 | M37: =M38+M39+M40 -> -28465.71 | ... R37: =R38+R39+R40 -> -338798.97 | T37: =SUM(F37:K37) -> -272843.33 | U37: =SUM(L37:Q37) -> -65955.644 | V37: =T37+U37 -> -338798.97
D38: ISS - V E | F38: ='Cálculos de Impostos'!F38 -> -46382.452 | G38: ='Cálculos de Impostos'!G38 -> -32444.43 | H38: ='Cálculos de Impostos'!H38 -> -33064.732 | I38: ='Cálculos de Impostos'!I38 -> -34245.428 | J38: ='Cálculos de Impostos'!J38 -> -13572.593 | K38: ='Cálculos de Impostos'!K38 -> -17709.308 | L38: ='Cálculos de Impostos'!L38 -> -21565.747 | M38: ='Cálculos de Impostos'!M38 -> -15015.573 | ... Q38: ='Cálculos de Impostos'!Q38 -> 0 | R38: =SUM(F38:Q38) -> -214000.26 | T38: =SUM(F38:K38) -> -177418.94 | U38: =SUM(L38:Q38) -> -36581.321 | V38: =T38+U38 -> -214000.26
D39: ISS - SPDX | F39: ='Cálculos de Impostos'!F39 -> -3104.7323 | G39: ='Cálculos de Impostos'!G39 -> -2982.927 | H39: ='Cálculos de Impostos'!H39 -> -2914.6722 | I39: ='Cálculos de Impostos'!I39 -> -2882.5492 | J39: ='Cálculos de Impostos'!J39 -> -3033.7037 | K39: ='Cálculos de Impostos'!K39 -> -3035.6522 | L39: ='Cálculos de Impostos'!L39 -> -3122.0034 | M39: ='Cálculos de Impostos'!M39 -> -3202.8638 | ... Q39: ='Cálculos de Impostos'!Q39 -> 0 | R39: =SUM(F39:Q39) -> -24279.104 | T39: =SUM(F39:K39) -> -17954.237 | U39: =SUM(L39:Q39) -> -6324.8672 | V39: =T39+U39 -> -24279.104
D40: ISS - Dataforte | F40: ='Cálculos de Impostos'!F40 -> -13333.823 | G40: ='Cálculos de Impostos'!G40 -> -9343.4413 | H40: ='Cálculos de Impostos'!H40 -> -9875.4655 | I40: ='Cálculos de Impostos'!I40 -> -9954.2426 | J40: ='Cálculos de Impostos'!J40 -> -24027.905 | K40: ='Cálculos de Impostos'!K40 -> -10935.269 | L40: ='Cálculos de Impostos'!L40 -> -12802.183 | M40: ='Cálculos de Impostos'!M40 -> -10247.273 | ... Q40: ='Cálculos de Impostos'!Q40 -> 0 | R40: =SUM(F40:Q40) -> -100519.6 | T40: =SUM(F40:K40) -> -77470.147 | U40: =SUM(L40:Q40) -> -23049.456 | V40: =T40+U40 -> -100519.6
B41: Receita Operacional Líquida | F41: =F4+F27 -> 1582207.8 | G41: =G4+G27 -> 1204257.7 | H41: =H4+H27 -> 1371332.6 | I41: =I4+I27 -> 1343845.5 | J41: =J4+J27 -> 1521704.5 | K41: =K4+K27 -> 1378073.3 | L41: =L4+L27 -> 1572185.9 | M41: =M4+M27 -> 1327607.9 | ... R41: =R4+R27 -> 11301215 | T41: =SUM(F41:K41) -> 8401421.4 | U41: =SUM(L41:Q41) -> 2899793.7 | V41: =T41+U41 -> 11301215
B42: Custos com os Serviços Prestados | F42: =SUM(F43:F47) -> -75616.964 | G42: =SUM(G43:G47) -> -46012.15 | H42: =SUM(H43:H47) -> -61394.776 | I42: =SUM(I43:I47) -> -52504.502 | J42: =SUM(J43:J47) -> -235852.36 | K42: =SUM(K43:K47) -> -30271.711 | L42: =SUM(L43:L47) -> -54339.315 | M42: =SUM(M43:M47) -> -14711.093 | ... R42: =SUM(R43:R47) -> -570702.87 | T42: =SUM(F42:K42) -> -501652.47 | U42: =SUM(L42:Q42) -> -69050.408 | V42: =T42+U42 -> -570702.87
...

Sheet Cálculos de Impostos
F2: janeiro | G2: fevereiro | H2: março | I2: abril | J2: maio | K2: junho | L2: julho | M2: agosto | N2: setembro | O2: outubro | P2: novembro | Q2: dezembro | R2: 2026 | T2: 1 SEM | U2: 2 SEM | V2: 2024
B4: Receita Operacional Bruta | F4: =F5+F8+F11+F14+F15+F16+F17+F21+F22+F23 -> 1686702.6 | G4: =G5+G8+G11+G14+G15+G16+G17+G21+G22+G23 -> 1279880.2 | H4: =H5+H8+H11+H14+H15+H16+H17+H21+H22+H23 -> 1452060.6 | I4: =I5+I8+I11+I14+I15+I16+I17+I21+I22+I23 -> 1422561.5 | J4: =J5+J8+J11+J14+J15+J16+J17+J21+J22+J23 -> 1596280.6 | K4: =K5+K8+K11+K14+K15+K16+K17+K21+K22+K23 -> 1566052 | L4: =L5+L8+L11+L14+L15+L16+L17+L21+L22+L23 -> 1647475.2 | M4: =M5+M8+M11+M14+M15+M16+M17+M21+M22+M23 -> 1388629.3 | ... R4: =R5+R8+R11+R14+R15+R16+R17+R21+R22+R23 -> 12039642 | T4: =SUM(F4:K4) -> 9003537.4 | U4: =SUM(L4:Q4) -> 3036104.5 | V4: =T4+U4 -> 12039642
C5: Royalties | F5: =SUM(F6:F7) -> 858569.87 | G5: =SUM(G6:G7) -> 598623.74 | H5: =SUM(H6:H7) -> 606841.34 | I5: =SUM(I6:I7) -> 632427.22 | J5: =SUM(J6:J7) -> 530748.99 | K5: =SUM(K6:K7) -> 750091.11 | L5: =SUM(L6:L7) -> 765899.31 | M5: =SUM(M6:M7) -> 606346.88 | ... R5: =SUM(R6:R7) -> 5349548.5 | T5: =SUM(F5:K5) -> 3977302.3 | U5: =SUM(L5:Q5) -> 1372246.2 | V5: =T5+U5 -> 5349548.5
D6: Royalties - Recorrentes | F6: ='Outras Informações'!B5 -> 742596.16 | G6: ='Outras Informações'!C5 -> 520688.71 | H6: ='Outras Informações'!D5 -> 578703 | I6: ='Outras Informações'!E5 -> 609147.54 | J6: ='Outras Informações'!F5 -> 518335.49 | K6: ='Outras Informações'!G5 -> 638364.5 | L6: ='Outras Informações'!H5 -> 678311.33 | M6: ='Outras Informações'!I5 -> 534530.06 | ... Q6: ='Outras Informações'!M5 -> 0 | R6: =SUM(F6:Q6) -> 4820676.8 | T6: =SUM(F6:K6) -> 3607835.4 | U6: =SUM(L6:Q6) -> 1212841.4 | V6: =T6+U6 -> 4820676.8
D7: Royalties - Fechamentos | F7: ='Outras Informações'!B6 -> 115973.71 | G7: ='Outras Informações'!C6 -> 77935.03 | H7: ='Outras Informações'!D6 -> 28138.34 | I7: ='Outras Informações'!E6 -> 23279.68 | J7: ='Outras Informações'!F6 -> 12413.5 | K7: ='Outras Informações'!G6 -> 111726.61 | L7: ='Outras Informações'!H6 -> 87587.98 | M7: ='Outras Informações'!I6 -> 71816.82 | ... Q7: ='Outras Informações'!M6 -> 0 | R7: =SUM(F7:Q7) -> 528871.67 | T7: =SUM(F7:K7) -> 369466.87 | U7: =SUM(L7:Q7) -> 159404.8 | V7: =T7+U7 -> 528871.67
C8: Fundo de Marketing | F8: =SUM(F9:F10) -> 53494.86 | G8: =SUM(G9:G10) -> 36027.51 | H8: =SUM(H9:H10) -> 40270.14 | I8: =SUM(I9:I10) -> 37264.5 | J8: =SUM(J9:J10) -> 36951.48 | K8: =SUM(K9:K10) -> 46118.45 | L8: =SUM(L9:L10) -> 45244.39 | M8: =SUM(M9:M10) -> 38702.04 | ... R8: =SUM(R9:R10) -> 334073.37 | T8: =SUM(F8:K8) -> 250126.94 | U8: =SUM(L8:Q8) -> 83946.43 | V8: =T8+U8 -> 334073.37
D9: Fundo de Marketing - Recorrentes | F9: ='Outras Informações'!B7 -> 46209.41 | G9: ='Outras Informações'!C7 -> 30939.14 | H9: ='Outras Informações'!D7 -> 38474.08 | I9: ='Outras Informações'!E7 -> 35766.61 | J9: ='Outras Informações'!F7 -> 32874.72 | K9: ='Outras Informações'!G7 -> 44826.72 | L9: ='Outras Informações'!H7 -> 43952.66 | M9: ='Outras Informações'!I7 -> 36368.87 | ... Q9: ='Outras Informações'!M7 -> 0 | R9: =SUM(F9:Q9) -> 309412.21 | T9: =SUM(F9:K9) -> 229090.68 | U9: =SUM(L9:Q9) -> 80321.53 | V9: =T9+U9 -> 309412.21
D10: Fundo de Marketing - Fechamentos | F10: ='Outras Informações'!B8 -> 7285.45 | G10: ='Outras Informações'!C8 -> 5088.37 | H10: ='Outras Informações'!D8 -> 1796.06 | I10: ='Outras Informações'!E8 -> 1497.89 | J10: ='Outras Informações'!F8 -> 4076.76 | K10: ='Outras Informações'!G8 -> 1291.73 | L10: ='Outras Informações'!H8 -> 1291.73 | M10: ='Outras Informações'!I8 -> 2333.17 | ... Q10: ='Outras Informações'!M8 -> 0 | R10: =SUM(F10:Q10) -> 24661.16 | T10: =SUM(F10:K10) -> 21036.26 | U10: =SUM(L10:Q10) -> 3624.9 | V10: =T10+U10 -> 24661.16
C11: Taxas de Franquias | F11: =F12+F13 -> 0 | G11: =G12+G13 -> 0 | H11: =H12+H13 -> 0 | I11: =I12+I13 -> 0 | J11: =J12+J13 -> 0 | K11: =K12+K13 -> 0 | L11: =L12+L13 -> 0 | M11: =M12+M13 -> 0 | ... R11: =R12+R13 -> 0 | T11: =SUM(F11:K11) -> 0 | U11: =SUM(L11:Q11) -> 0 | V11: =T11+U11 -> 0
D12: Taxa Inicial de Franquia | F12: ='Outras Informações'!B65 -> 0 | G12: ='Outras Informações'!C65 -> 0 | H12: ='Outras Informações'!D65 -> 0 | I12: ='Outras Informações'!E65 -> 0 | J12: ='Outras Informações'!F65 -> 0 | K12: ='Outras Informações'!G65 -> 0 | L12: ='Outras Informações'!H65 -> 0 | M12: ='Outras Informações'!I65 -> 0 | ... Q12: ='Outras Informações'!M65 -> 0 | R12: =SUM(F12:Q12) -> 0 | T12: =SUM(F12:K12) -> 0 | U12: =SUM(L12:Q12) -> 0 | V12: =T12+U12 -> 0
D13: Renovação de Franquias | F13: ='Outras Informações'!B74 -> 0 | G13: ='Outras Informações'!C74 -> 0 | H13: ='Outras Informações'!D74 -> 0 | I13: ='Outras Informações'!E74 -> 0 | J13: ='Outras Informações'!F74 -> 0 | K13: ='Outras Informações'!G74 -> 0 | L13: ='Outras Informações'!H74 -> 0 | M13: ='Outras Informações'!I74 -> 0 | ... Q13: ='Outras Informações'!M74 -> 0 | R13: =SUM(F13:Q13) -> 0 | T13: =SUM(F13:K13) -> 0 | U13: =SUM(L13:Q13) -> 0 | V13: =T13+U13 -> 0
C14: Receita com Patrocínios | F14: ='Outras Informações'!B9 -> 0 | G14: ='Outras Informações'!C9 -> 0 | H14: ='Outras Informações'!D9 -> 0 | I14: ='Outras Informações'!E9 -> 0 | J14: ='Outras Informações'!F9 -> 0 | K14: ='Outras Informações'!G9 -> 0 | L14: ='Outras Informações'!H9 -> 0 | M14: ='Outras Informações'!I9 -> 0 | ... Q14: ='Outras Informações'!M9 -> 0 | R14: =SUM(F14:Q14) -> 0 | T14: =SUM(F14:K14) -> 0 | U14: =SUM(L14:Q14) -> 0 | V14: =T14+U14 -> 0
C15: Receita SPDX | F15: ='Outras Informações'!B10 -> 435100.22 | G15: ='Outras Informações'!C10 -> 385150.49 | H15: ='Outras Informações'!D10 -> 538232.09 | I15: ='Outras Informações'!E10 -> 487174.31 | J15: ='Outras Informações'!F10 -> 486610.35 | K15: ='Outras Informações'!G10 -> 486259.18 | L15: ='Outras Informações'!H10 -> 517608.2 | M15: ='Outras Informações'!I10 -> 467285.15 | ... Q15: ='Outras Informações'!M10 -> 0 | R15: =SUM(F15:Q15) -> 3803420 | T15: =SUM(F15:K15) -> 2818526.6 | U15: =SUM(L15:Q15) -> 984893.35 | V15: =T15+U15 -> 3803420
C16: Receitas - Taxa Mundo Viva | F16: ='Outras Informações'!B11 -> 76119.7 | G16: ='Outras Informações'!C11 -> 73017 | H16: ='Outras Informações'!D11 -> 71232.9 | I16: ='Outras Informações'!E11 -> 70336.1 | J16: ='Outras Informações'!F11 -> 73790.3 | K16: ='Outras Informações'!G11 -> 73663 | L16: ='Outras Informações'!H11 -> 76239.4 | M16: ='Outras Informações'!I11 -> 77537.1 | ... Q16: ='Outras Informações'!M11 -> 0 | R16: =SUM(F16:Q16) -> 591935.5 | T16: =SUM(F16:K16) -> 438159 | U16: =SUM(L16:Q16) -> 153776.5 | V16: =T16+U16 -> 591935.5
C17: Receitas - Markup de Tarifas | F17: =F18+F19+F20 -> 175537.31 | G17: =G18+G19+G20 -> 105459.15 | H17: =H18+H19+H20 -> 115377.65 | I17: =I18+I19+I20 -> 107690.23 | J17: =J18+J19+J20 -> 125373.64 | K17: =K18+K19+K20 -> 130235.64 | L17: =L18+L19+L20 -> 159580.33 | M17: =M18+M19+M20 -> 110404.67 | ... R17: =R18+R19+R20 -> 1029658.6 | T17: =SUM(F17:K17) -> 759673.62 | U17: =SUM(L17:Q17) -> 269985 | V17: =T17+U17 -> 1029658.6
D18: Markup de Liquidação de boletos | F18: ='Outras Informações'!B12 -> 33721.79 | G18: ='Outras Informações'!C12 -> 29503.82 | H18: ='Outras Informações'!D12 -> 37861.57 | I18: ='Outras Informações'!E12 -> 31977.18 | J18: ='Outras Informações'!F12 -> 32255.93 | K18: ='Outras Informações'!G12 -> 37591.02 | L18: ='Outras Informações'!H12 -> 39603.36 | M18: ='Outras Informações'!I12 -> 36696.37 | ... Q18: ='Outras Informações'!M12 -> 0 | R18: =SUM(F18:Q18) -> 279211.04 | T18: =SUM(F18:K18) -> 202911.31 | U18: =SUM(L18:Q18) -> 76299.73 | V18: =T18+U18 -> 279211.04
D19: Markup de cartão | F19: ='Outras Informações'!B13 -> 138056.49 | G19: ='Outras Informações'!C13 -> 72990.74 | H19: ='Outras Informações'!D13 -> 73001.08 | I19: ='Outras Informações'!E13 -> 73181.66 | J19: ='Outras Informações'!F13 -> 90920.72 | K19: ='Outras Informações'!G13 -> 89856.48 | L19: ='Outras Informações'!H13 -> 116286.7 | M19: ='Outras Informações'!I13 -> 70079.12 | ... Q19: ='Outras Informações'!M13 -> 0 | R19: =SUM(F19:Q19) -> 724372.99 | T19: =SUM(F19:K19) -> 538007.17 | U19: =SUM(L19:Q19) -> 186365.82 | V19: =T19+U19 -> 724372.99
D20: Markup de tarifas bancárias | F20: ='Outras Informações'!B14 -> 3759.03 | G20: ='Outras Informações'!C14 -> 2964.59 | H20: ='Outras Informações'!D14 -> 4515 | I20: ='Outras Informações'!E14 -> 2531.39 | J20: ='Outras Informações'!F14 -> 2196.99 | K20: ='Outras Informações'!G14 -> 2788.14 | L20: ='Outras Informações'!H14 -> 3690.27 | M20: ='Outras Informações'!I14 -> 3629.18 | ... Q20: ='Outras Informações'!M14 -> 0 | R20: =SUM(F20:Q20) -> 26074.59 | T20: =SUM(F20:K20) -> 18755.14 | U20: =SUM(L20:Q20) -> 7319.45 | V20: =T20+U20 -> 26074.59
C21: Receitas - Festas de Arrecadação | F21: ='Outras Informações'!B15 -> 3762.29 | G21: ='Outras Informações'!C15 -> 6307.8 | H21: ='Outras Informações'!D15 -> 6771.63 | I21: ='Outras Informações'!E15 -> 7115.56 | J21: ='Outras Informações'!F15 -> 263540.41 | K21: ='Outras Informações'!G15 -> 12085.48 | L21: ='Outras Informações'!H15 -> 9083.4 | M21: ='Outras Informações'!I15 -> 10163.01 | ... Q21: ='Outras Informações'!M15 -> 0 | R21: =SUM(F21:Q21) -> 318829.58 | T21: =SUM(F21:K21) -> 299583.17 | U21: =SUM(L21:Q21) -> 19246.41 | V21: =T21+U21 -> 318829.58
C22: Receita com Projetos | F22: ='Outras Informações'!B16 -> 1640.5782 | G22: ='Outras Informações'!C16 -> 1146.6088 | H22: ='Outras Informações'!D16 -> 1200.1852 | I22: ='Outras Informações'!E16 -> 220.52859 | J22: ='Outras Informações'!F16 -> 146.8843 | K22: ='Outras Informações'!G16 -> 984.60246 | L22: ='Outras Informações'!H16 -> 2093.0596 | M22: ='Outras Informações'!I16 -> 1140.343 | ... Q22: ='Outras Informações'!M16 -> 0 | R22: =SUM(F22:Q22) -> 8572.7901 | T22: =SUM(F22:K22) -> 5339.3876 | U22: =SUM(L22:Q22) -> 3233.4026 | V22: =T22+U22 -> 8572.7901
C23: Receitas - Assessoria CSC | F23: =F24+F25+F26 -> 82477.8 | G23: =G24+G25+G26 -> 74147.94 | H23: =H24+H25+H26 -> 72134.63 | I23: =I24+I25+I26 -> 80333.03 | J23: =J24+J25+J26 -> 79118.51 | K23: =K24+K25+K26 -> 66614.5 | L23: =L24+L25+L26 -> 71727.16 | M23: =M24+M25+M26 -> 77050.1 | ... R23: =R24+R25+R26 -> 603603.67 | T23: =SUM(F23:K23) -> 454826.41 | U23: =SUM(L23:Q23) -> 148777.26 | V23: =T23+U23 -> 603603.67
D24: Assessoria CSC - Quokka | F24: ='Outras Informações'!B17 -> 49703 | G24: ='Outras Informações'!C17 -> 46767 | H24: ='Outras Informações'!D17 -> 41835.5 | I24: ='Outras Informações'!E17 -> 41835.5 | J24: ='Outras Informações'!F17 -> 45335.5 | K24: ='Outras Informações'!G17 -> 40214.5 | L24: ='Outras Informações'!H17 -> 39404 | M24: ='Outras Informações'!I17 -> 37783 | ... Q24: ='Outras Informações'!M17 -> 0 | R24: =SUM(F24:Q24) -> 342878 | T24: =SUM(F24:K24) -> 265691 | U24: =SUM(L24:Q24) -> 77187 | V24: =T24+U24 -> 342878
D25: Assessoria Central de Talentos | F25: ='Outras Informações'!B18 -> 3774.8 | G25: ='Outras Informações'!C18 -> 3380.94 | H25: ='Outras Informações'!D18 -> 5299.13 | I25: ='Outras Informações'!E18 -> 12245.03 | J25: ='Outras Informações'!F18 -> 4283.01 | K25: ='Outras Informações'!G18 -> 0 | L25: ='Outras Informações'!H18 -> 3023.16 | M25: ='Outras Informações'!I18 -> 4967.1 | ... Q25: ='Outras Informações'!M18 -> 0 | R25: =SUM(F25:Q25) -> 36973.17 | T25: =SUM(F25:K25) -> 28982.91 | U25: =SUM(L25:Q25) -> 7990.26 | V25: =T25+U25 -> 36973.17
D26: Assessoria CSC - Atendimento | F26: ='Outras Informações'!B19 -> 29000 | G26: ='Outras Informações'!C19 -> 24000 | H26: ='Outras Informações'!D19 -> 25000 | I26: ='Outras Informações'!E19 -> 26252.5 | J26: ='Outras Informações'!F19 -> 29500 | K26: ='Outras Informações'!G19 -> 26400 | L26: ='Outras Informações'!H19 -> 29300 | M26: ='Outras Informações'!I19 -> 34300 | ... Q26: ='Outras Informações'!M19 -> 0 | R26: =SUM(F26:Q26) -> 223752.5 | T26: =SUM(F26:K26) -> 160152.5 | U26: =SUM(L26:Q26) -> 63600 | V26: =T26+U26 -> 223752.5
B27: Deduções de Receita | F27: =F28+F29+F33+F37 -> -104494.82 | G27: =G28+G29+G33+G37 -> -75622.536 | H27: =H28+H29+H33+H37 -> -80727.962 | I27: =I28+I29+I33+I37 -> -78716.017 | J27: =J28+J29+J33+J37 -> -74576.061 | K27: =K28+K29+K33+K37 -> -187978.64 | L27: =L28+L29+L33+L37 -> -75289.378 | M27: =M28+M29+M33+M37 -> -61021.424 | ... Q27: =Q28+Q29+Q33+Q37 -> 0 | R27: =SUM(F27:Q27) -> -738426.84 | T27: =SUM(F27:K27) -> -602116.04 | U27: =SUM(L27:Q27) -> -136310.8 | V27: =T27+U27 -> -738426.84
C28: Devoluções de Vendas de Serviços Prestados | F28: =SUMIFS('Lançamentos Omie'!$G:$G,'Lançamentos Omie'!$I:$I,$C28,'Lançamentos Omie'!$F:$F,F$2) -> -19.64 | G28: =SUMIFS('Lançamentos Omie'!$G:$G,'Lançamentos Omie'!$I:$I,$C28,'Lançamentos Omie'!$F:$F,G$2) -> -1292.74 | H28: =SUMIFS('Lançamentos Omie'!$G:$G,'Lançamentos Omie'!$I:$I,$C28,'Lançamentos Omie'!$F:$F,H$2) -> -4648.39 | I28: =SUMIFS('Lançamentos Omie'!$G:$G,'Lançamentos Omie'!$I:$I,$C28,'Lançamentos Omie'!$F:$F,I$2) -> -526.91 | J28: =SUMIFS('Lançamentos Omie'!$G:$G,'Lançamentos Omie'!$I:$I,$C28,'Lançamentos Omie'!$F:$F,J$2) -> 0 | K28: =SUMIFS('Lançamentos Omie'!$G:$G,'Lançamentos Omie'!$I:$I,$C28,'Lançamentos Omie'!$F:$F,K$2) -> -120275.68 | L28: =SUMIFS('Lançamentos Omie'!$G:$G,'Lançamentos Omie'!$I:$I,$C28,'Lançamentos Omie'!$F:$F,L$2) -> 0 | M28: =SUMIFS('Lançamentos Omie'!$G:$G,'Lançamentos Omie'!$I:$I,$C28,'Lançamentos Omie'!$F:$F,M$2) -> -2177.59 | ... Q28: =SUMIFS('Lançamentos Omie'!$G:$G,'Lançamentos Omie'!$I:$I,$C28,'Lançamentos Omie'!$F:$F,Q$2) -> 0 | R28: =SUM(F28:Q28) -> -128940.95 | T28: =SUM(F28:K28) -> -126763.36 | U28: =SUM(L28:Q28) -> -2177.59 | V28: =T28+U28 -> -128940.95
C29: PIS | F29: =F30+F31+F32 -> -7418.9965 | G29: =G30+G31+G32 -> -5264.8179 | H29: =H30+H31+H32 -> -5383.3907 | I29: =I30+I31+I32 -> -5540.4929 | J29: =J30+J31+J32 -> -6046.1741 | K29: =K30+K31+K32 -> -6415.9908 | L29: =L30+L31+L32 -> -6732.5094 | M29: =M30+M31+M32 -> -5410.7675 | ... R29: =R30+R31+R32 -> -48213.14 | T29: =SUM(F29:K29) -> -36069.863 | U29: =SUM(L29:Q29) -> -12143.277 | V29: =T29+U29 -> -48213.14
D30: PIS - V E | F30: =-0.65%*(F5+F8+F11+F14)-0.65%*F102 -> -6029.7188 | G30: =-0.65%*(G5+G8+G11+G14)-0.65%*G102 -> -4217.776 | H30: =-0.65%*(H5+H8+H11+H14)-0.65%*H102 -> -4298.4151 | I30: =-0.65%*(I5+I8+I11+I14)-0.65%*I102 -> -4451.9056 | J30: =-0.65%*(J5+J8+J11+J14)-0.65%*J102 -> -3775.9162 | K30: =-0.65%*(K5+K8+K11+K14)-0.65%*K102 -> -5232.0488 | L30: =-0.65%*(L5+L8+L11+L14)-0.65%*L102 -> -5385.7768 | M30: =-0.65%*(M5+M8+M11+M14)-0.65%*M102 -> -4268.6898 | ... Q30: =-0.65%*(Q5+Q8+Q11+Q14)-0.65%*Q102 -> 0 | R30: =SUM(F30:Q30) -> -37660.247 | T30: =SUM(F30:K30) -> -28005.78 | U30: =SUM(L30:Q30) -> -9654.4666 | V30: =T30+U30 -> -37660.247
D31: PIS - SPDX | F31: =-('Outras Informações'!B90*2.96%*(F16)) -> -282.76946 | G31: =-('Outras Informações'!C90*2.96%*(G16)) -> -271.67581 | H31: =-('Outras Informações'!D90*2.96%*(H16)) -> -265.45937 | I31: =-('Outras Informações'!E90*2.96%*(I16)) -> -262.53371 | J31: =-('Outras Informações'!F90*2.96%*(J16)) -> -276.3004 | K31: =-('Outras Informações'!G90*2.96%*(K16)) -> -276.47786 | L31: =-('Outras Informações'!H90*2.96%*(L16)) -> -284.34247 | M31: =-('Outras Informações'!I90*2.96%*(M16)) -> -291.70698 | ... Q31: =-('Outras Informações'!M90*2.96%*(Q16)) -> 0 | R31: =SUM(F31:Q31) -> -2211.2661 | T31: =SUM(F31:K31) -> -1635.2166 | U31: =SUM(L31:Q31) -> -576.04944 | V31: =T31+U31 -> -2211.2661
D32: PIS - Dataforte | F32: =-('Outras Informações'!B89*2.78%*(F17+F21+F22+F23)) -> -1106.5083 | G32: =-('Outras Informações'!C89*2.78%*(G17+G21+G22+G23)) -> -775.36617 | H32: =-('Outras Informações'!D89*2.78%*(H17+H21+H22+H23)) -> -819.51624 | I32: =-('Outras Informações'!E89*2.78%*(I17+I21+I22+I23)) -> -826.05356 | J32: =-('Outras Informações'!F89*2.78%*(J17+J21+J22+J23)) -> -1993.9575 | K32: =-('Outras Informações'!G89*2.78%*(K17+K21+K22+K23)) -> -907.46413 | L32: =-('Outras Informações'!H89*2.78%*(L17+L21+L22+L23)) -> -1062.3901 | M32: =-('Outras Informações'!I89*2.78%*(M17+M21+M22+M23)) -> -850.37073 | ... Q32: =-('Outras Informações'!M89*2.78%*(Q17+Q21+Q22+Q23)) -> 0 | R32: =SUM(F32:Q32) -> -8341.6267 | T32: =SUM(F32:K32) -> -6428.8659 | U32: =SUM(L32:Q32) -> -1912.7608 | V32: =T32+U32 -> -8341.6267
C33: COFINS | F33: =F34+F35+F36 -> -34235.178 | G33: =G34+G35+G36 -> -24294.179 | H33: =H34+H35+H36 -> -24841.312 | I33: =I34+I35+I36 -> -25566.395 | J33: =J34+J35+J36 -> -27895.684 | K33: =K34+K35+K36 -> -29606.738 | L33: =L34+L35+L36 -> -31066.936 | M33: =M34+M35+M36 -> -24967.356 | ... R33: =R34+R35+R36 -> -222473.78 | T33: =SUM(F33:K33) -> -166439.49 | U33: =SUM(L33:Q33) -> -56034.292 | V33: =T33+U33 -> -222473.78
D34: COFINS - V E | F34: =-3%*(F5+F8+F11+F14)-3%*F102 -> -27829.471 | G34: =-3%*(G5+G8+G11+G14)-3%*G102 -> -19466.658 | H34: =-3%*(H5+H8+H11+H14)-3%*H102 -> -19838.839 | I34: =-3%*(I5+I8+I11+I14)-3%*I102 -> -20547.256 | J34: =-3%*(J5+J8+J11+J14)-3%*J102 -> -17427.305 | K34: =-3%*(K5+K8+K11+K14)-3%*K102 -> -24147.918 | L34: =-3%*(L5+L8+L11+L14)-3%*L102 -> -24857.431 | M34: =-3%*(M5+M8+M11+M14)-3%*M102 -> -19701.645 | ... Q34: =-3%*(Q5+Q8+Q11+Q14)-3%*Q102 -> 0 | R34: =SUM(F34:Q34) -> -173816.52 | T34: =SUM(F34:K34) -> -129257.45 | U34: =SUM(L34:Q34) -> -44559.077 | V34: =T34+U34 -> -173816.52
D35: COFINS - SPDX | F35: =-('Outras Informações'!B90*13.64%*(F16)) -> -1303.0322 | G35: =-('Outras Informações'!C90*13.64%*(G16)) -> -1251.9115 | H35: =-('Outras Informações'!D90*13.64%*(H16)) -> -1223.2655 | I35: =-('Outras Informações'!E90*13.64%*(I16)) -> -1209.7837 | J35: =-('Outras Informações'!F90*13.64%*(J16)) -> -1273.2221 | K35: =-('Outras Informações'!G90*13.64%*(K16)) -> -1274.0399 | L35: =-('Outras Informações'!H90*13.64%*(L16)) -> -1310.2808 | M35: =-('Outras Informações'!I90*13.64%*(M16)) -> -1344.2173 | ... Q35: =-('Outras Informações'!M90*13.64%*(Q16)) -> 0 | R35: =SUM(F35:Q35) -> -10189.753 | T35: =SUM(F35:K35) -> -7535.255 | U35: =SUM(L35:Q35) -> -2654.4981 | V35: =T35+U35 -> -10189.753
D36: COFINS - Dataforte | F36: =-('Outras Informações'!B89*12.82%*(F17+F21+F22+F23)) -> -5102.6749 | G36: =-('Outras Informações'!C89*12.82%*(G17+G21+G22+G23)) -> -3575.6095 | H36: =-('Outras Informações'!D89*12.82%*(H17+H21+H22+H23)) -> -3779.208 | I36: =-('Outras Informações'!E89*12.82%*(I17+I21+I22+I23)) -> -3809.3549 | J36: =-('Outras Informações'!F89*12.82%*(J17+J21+J22+J23)) -> -9195.1566 | K36: =-('Outras Informações'!G89*12.82%*(K17+K21+K22+K23)) -> -4184.7806 | L36: =-('Outras Informações'!H89*12.82%*(L17+L21+L22+L23)) -> -4899.2233 | M36: =-('Outras Informações'!I89*12.82%*(M17+M21+M22+M23)) -> -3921.4938 | ... Q36: =-('Outras Informações'!M89*12.82%*(Q17+Q21+Q22+Q23)) -> 0 | R36: =SUM(F36:Q36) -> -38467.502 | T36: =SUM(F36:K36) -> -29646.785 | U36: =SUM(L36:Q36) -> -8820.7171 | V36: =T36+U36 -> -38467.502
C37: ISS | F37: =F38+F39+F40 -> -62821.007 | G37: =G38+G39+G40 -> -44770.799 | H37: =H38+H39+H40 -> -45854.869 | I37: =I38+I39+I40 -> -47082.219 | J37: =J38+J39+J40 -> -40634.203 | K37: =K38+K39+K40 -> -31680.229 | L37: =L38+L39+L40 -> -37489.933 | M37: =M38+M39+M40 -> -28465.71 | ... R37: =R38+R39+R40 -> -338798.97 | T37: =SUM(F37:K37) -> -272843.33 | U37: =SUM(L37:Q37) -> -65955.644 | V37: =T37+U37 -> -338798.97
D38: ISS - V E | F38: =-5%*(F5+F8+F11+F14)-5%*F102 -> -46382.452 | G38: =-5%*(G5+G8+G11+G14)-5%*G102 -> -32444.43 | H38: =-5%*(H5+H8+H11+H14)-5%*H102 -> -33064.732 | I38: =-5%*(I5+I8+I11+I14)-5%*I102 -> -34245.428 | J38: =-5%*('Outras Informações'!F60+J11+J14)-5%*J102-2%*'Outras Informações'!F61 -> -13572.593 | K38: =-5%*('Outras Informações'!G60+K11+K14)-5%*K102-2%*'Outras Informações'!G61 -> -17709.308 | L38: =-5%*('Outras Informações'!H60+L11+L14)-5%*L102-2%*'Outras Informações'!H61 -> -21565.747 | M38: =-5%*('Outras Informações'!I60+M11+M14)-5%*M102-2%*'Outras Informações'!I61 -> -15015.573 | N38: =-5%*('Outras Informações'!J60+N11+N14)-5%*N102-2%*'Outras Informações'!J61 -> 0 | O38: =-5%*('Outras Informações'!K60+O11+O14)-5%*O102-2%*'Outras Informações'!K61 -> 0 | P38: =-5%*('Outras Informações'!L60+P11+P14)-5%*P102-2%*'Outras Informações'!L61 -> 0 | Q38: =-5%*('Outras Informações'!M60+Q11+Q14)-5%*Q102-2%*'Outras Informações'!M61 -> 0 | R38: =SUM(F38:Q38) -> -214000.26 | T38: =SUM(F38:K38) -> -177418.94 | U38: =SUM(L38:Q38) -> -36581.321 | V38: =T38+U38 -> -214000.26
D39: ISS - SPDX | F39: =-('Outras Informações'!B90*32.5%*(F16)) -> -3104.7323 | G39: =-('Outras Informações'!C90*32.5%*(G16)) -> -2982.927 | H39: =-('Outras Informações'!D90*32.5%*(H16)) -> -2914.6722 | I39: =-('Outras Informações'!E90*32.5%*(I16)) -> -2882.5492 | J39: =-('Outras Informações'!F90*32.5%*(J16)) -> -3033.7037 | K39: =-('Outras Informações'!G90*32.5%*(K16)) -> -3035.6522 | L39: =-('Outras Informações'!H90*32.5%*(L16)) -> -3122.0034 | M39: =-('Outras Informações'!I90*32.5%*(M16)) -> -3202.8638 | ... Q39: =-('Outras Informações'!M90*32.5%*(Q16)) -> 0 | R39: =SUM(F39:Q39) -> -24279.104 | T39: =SUM(F39:K39) -> -17954.237 | U39: =SUM(L39:Q39) -> -6324.8672 | V39: =T39+U39 -> -24279.104
D40: ISS - Dataforte | F40: =-('Outras Informações'!B89*33.5%*(F17+F21+F22+F23)) -> -13333.823 | G40: =-('Outras Informações'!C89*33.5%*(G17+G21+G22+G23)) -> -9343.4413 | H40: =-('Outras Informações'!D89*33.5%*(H17+H21+H22+H23)) -> -9875.4655 | I40: =-('Outras Informações'!E89*33.5%*(I17+I21+I22+I23)) -> -9954.2426 | J40: =-('Outras Informações'!F89*33.5%*(J17+J21+J22+J23)) -> -24027.905 | K40: =-('Outras Informações'!G89*33.5%*(K17+K21+K22+K23)) -> -10935.269 | L40: =-('Outras Informações'!H89*33.5%*(L17+L21+L22+L23)) -> -12802.183 | M40: =-('Outras Informações'!I89*33.5%*(M17+M21+M22+M23)) -> -10247.273 | ... Q40: =-('Outras Informações'!M89*33.5%*(Q17+Q21+Q22+Q23)) -> 0 | R40: =SUM(F40:Q40) -> -100519.6 | T40: =SUM(F40:K40) -> -77470.147 | U40: =SUM(L40:Q40) -> -23049.456 | V40: =T40+U40 -> -100519.6
B41: Receita Operacional Líquida | F41: =F4+F27 -> 1582207.8 | G41: =G4+G27 -> 1204257.7 | H41: =H4+H27 -> 1371332.6 | I41: =I4+I27 -> 1343845.5 | J41: =J4+J27 -> 1521704.5 | K41: =K4+K27 -> 1378073.3 | L41: =L4+L27 -> 1572185.9 | M41: =M4+M27 -> 1327607.9 | ... R41: =R4+R27 -> 11301215 | T41: =SUM(F41:K41) -> 8401421.4 | U41: =SUM(L41:Q41) -> 2899793.7 | V41: =T41+U41 -> 11301215
B42: Custos com os Serviços Prestados | F42: =SUM(F43:F47) -> -75616.964 | G42: =SUM(G43:G47) -> -46012.15 | H42: =SUM(H43:H47) -> -61394.776 | I42: =SUM(I43:I47) -> -52504.502 | J42: =SUM(J43:J47) -> -235852.36 | K42: =SUM(K43:K47) -> -30271.711 | L42: =SUM(L43:L47) -> -54339.315 | M42: =SUM(M43:M47) -> -14711.093 | ... R42: =SUM(R43:R47) -> -570702.87 | T42: =SUM(F42:K42) -> -501652.47 | U42: =SUM(L42:Q42) -> -69050.408 | V42: =T42+U42 -> -570702.87
...

Sheet Lançamentos Omie
A1: Empresa | B1: Tipo | C1: Categoria | D1: Cliente ou Fornecedor (Nome Fantasia) | E1: Descrição | F1: Mês da Emissão | G1: Pago ou Recebido | H1: Valor da Conta | I1: Conta DRE | J1: Setor | K1: Observação
A2: V EVENTOS BRASIL LTDA | B2: 2. Contas a Pagar | C2: Ações de Endomarketing (*) | D2: 46.067.579 MICHELE SOARES HENRIQUES | E2: PIX - REF AÇÃO DIA DAS MULHERES 2026 | F2: Março | G2: -764 | H2: -764 | I2: Ações Endomarketing | J2: Gestão de Pessoas
A3: V EVENTOS BRASIL LTDA | B3: 2. Contas a Pagar | C3: Ações de Endomarketing (*) | D3: ALEXANDER DE BARROS ARAUJO | E3: PIX - REF AO HAPPY DE CARNAVAL - VALOR DO ORÇAMENTO | F3: Fevereiro | G3: -1800 | H3: -1800 | I3: Ações Endomarketing | J3: Gestão de Pessoas
A4: V EVENTOS BRASIL LTDA | B4: 2. Contas a Pagar | C4: Ações de Endomarketing (*) | D4: BK BRINDES E BEEK | E4: DIN - COMPRA DE BRINDES FIM DE ANO COLABORADORES - ENVIAR DIN PARA SALVATERRA MATRIZ - detalhes em anexo | F4: Janeiro | G4: -75.8 | H4: -75.8 | I4: Ações Endomarketing | J4: Gestão de Pessoas
A5: V EVENTOS BRASIL LTDA | B5: 2. Contas a Pagar | C5: Ações de Endomarketing (*) | D5: BK BRINDES E BEEK | E5: DIN - COMPRA DE BRINDES FIM DE ANO COLABORADORES - ENVIAR DIN PARA CUBO - detalhes em anexo | F5: Janeiro | G5: -379 | H5: -379 | I5: Ações Endomarketing | J5: Gestão de Pessoas
A6: V EVENTOS BRASIL LTDA | B6: 2. Contas a Pagar | C6: Ações de Endomarketing (*) | D6: CVC BRASIL | E6: BOL - REF A VIAGEM 10 ANOS - THOMAS - PARCELA xx/04 | F6: Abril | G6: -1051.86 | H6: -1051.86 | I6: Ações Endomarketing | J6: Gestão de Pessoas
A7: V EVENTOS BRASIL LTDA | B7: 2. Contas a Pagar | C7: Ações de Endomarketing (*) | D7: CVC JF NORTE VIAGENS LTDA | E7: PIX- REF A VIAGEM 10 ANOS - THOMAS - ENTRADA | F7: Abril | G7: -468 | H7: -468 | I7: Ações Endomarketing | J7: Gestão de Pessoas
A8: V EVENTOS BRASIL LTDA | B8: 2. Contas a Pagar | C8: Ações de Endomarketing (*) | D8: CVC JF NORTE VIAGENS LTDA | E8: PIX- REF A VIAGEM 10 ANOS - CRIS - ENTRADA | F8: Abril | G8: -498 | H8: -498 | I8: Ações Endomarketing | J8: Gestão de Pessoas
A9: V EVENTOS BRASIL LTDA | B9: 2. Contas a Pagar | C9: Ações de Endomarketing (*) | D9: DIONISIO SOUZA LOURO | E9: PIX - REF A AÇÃO TIME MKT | F9: Abril | G9: -110 | H9: -110 | I9: Ações Endomarketing | J9: Marketing e Growth
A10: V EVENTOS BRASIL LTDA | B10: 2. Contas a Pagar | C10: Ações de Endomarketing (*) | D10: DIVERSOS | E10: DIN - Compras para reunião lançamento de quarter DIA 20/01/2026 | F10: Janeiro | G10: -237.18 | H10: -237.18 | I10: Ações Endomarketing | J10: Gestão
A11: V EVENTOS BRASIL LTDA | B11: 2. Contas a Pagar | C11: Ações de Endomarketing (*) | D11: DIVERSOS | E11: PIX - REF A AÇÃO DO MÊS DE JANEIRO - TIME QUOKKA | F11: Janeiro | G11: -23.36 | H11: -23.36 | I11: Ações Endomarketing | J11: Financeiro CSC
A12: V EVENTOS BRASIL LTDA | B12: 2. Contas a Pagar | C12: Ações de Endomarketing (*) | D12: DIVERSOS | E12: DIN - Ação roleta de aniversário - ganhador João | F12: Março | G12: -50 | H12: -50 | I12: Ações Endomarketing | J12: Gestão de Pessoas
A13: V EVENTOS BRASIL LTDA | B13: 2. Contas a Pagar | C13: Ações de Endomarketing (*) | D13: EMPORIO DOS PAES JF LTDA | E13: PIX - REF A AÇÃO DO MÊS DE FEVEREIRO - TIME QUOKKA | F13: Fevereiro | G13: -68.4 | H13: -68.4 | I13: Ações Endomarketing | J13: Financeiro CSC
... A30: V EVENTOS BRASIL LTDA | B30: 2. Contas a Pagar | C30: Ações de Endomarketing (*) | D30: PEDRO PAULO DIAS DE SOUZA | E30: BOL - REF A REUNIÃO ATD - FEV / MARÇO / ABRIL | F30: Abril | G30: -600 | H30: -600 | I30: Ações Endomarketing | J30: Atendimento
A31: V EVENTOS BRASIL LTDA | B31: 2. Contas a Pagar | C31: Ações de Endomarketing (*) | D31: THOMAS SOUZA REIS | E31: PIX- REF A VIAGEM 10 ANOS - THOMAS | F31: Abril | G31: -1000 | H31: -1000 | I31: Ações Endomarketing | J31: Gestão de Pessoas | K31: Previsão
A32: V EVENTOS BRASIL LTDA | B32: 2. Contas a Pagar | C32: Ações de Endomarketing (*) | D32: THOMAS SOUZA REIS | E32: PIX - REF A AÇÃO CARRETA FURACÃO ESTORNO DE 195,77 NO DIA 22/04/2026 | F32: Abril | G32: -804.23 | H32: -804.23 | I32: Ações Endomarketing | J32: Gestão de Pessoas
A33: V EVENTOS BRASIL LTDA | B33: 2. Contas a Pagar | C33: Ações de Endomarketing (*) | D33: THOMAS SOUZA REIS | E33: PIX - REF A AÇÃO TIME CAF | F33: Março | G33: -200 | H33: -200 | I33: Ações Endomarketing | J33: Pós Vendas e CAF
A34: V EVENTOS BRASIL LTDA | B34: 2. Contas a Pagar | C34: Ações de Endomarketing (*) | D34: TRINCA CAMISAS PERSONALIZADAS | E34: Incluído pela importação a partir de um código de barras. BOL - Ref a compra de camisas para venda da lojinha - campanha viva 2026 - venda master plan | F34: Janeiro | G34: -1317.8 | H34: -1317.8 | I34: Ações Endomarketing | J34: Gestão de Pessoas
A35: V EVENTOS BRASIL LTDA | B35: 2. Contas a Pagar | C35: Ações de Endomarketing (*) | D35: UBER DO BRASIL TECNOLOGIA LTDA. | E35: REF UBER - REGIS - Vt festa final de ano | F35: Janeiro | G35: -42.44 | H35: -42.44 | I35: Ações Endomarketing | J35: Gestão de Pessoas
A36: V EVENTOS BRASIL LTDA | B36: 2. Contas a Pagar | C36: Ações de Endomarketing (*) | D36: UBER DO BRASIL TECNOLOGIA LTDA. | E36: REF UBER - Guilherme - Visita tecnica brinde final de ano R$ 35,83 + Comboio do bem R$ 48,82 | F36: Janeiro | G36: -84.65 | H36: -84.65 | I36: Ações Endomarketing | J36: Gestão de Pessoas
A37: V EVENTOS BRASIL LTDA | B37: 2. Contas a Pagar | C37: Ações Endomarketing | D37: ASSUNTA | E37: Incluído a partir do recebimento da NF-e. PIX- REUNIÃO DE SÓCIOS 15/01 | F37: Janeiro | G37: -3134.8 | H37: -3134.8 | I37: Ações Endomarketing | J37: Diretoria
A38: V EVENTOS BRASIL LTDA | B38: 2. Contas a Pagar | C38: Ações Endomarketing | D38: COMERCIAL MEGA BRINDES | E38: Incluído a partir do recebimento da NF-e. BOL - REF A COMPRA DE ITENS PARA O KIT ONBOARDING | F38: Março | G38: -977 | H38: -977 | I38: Ações Endomarketing | J38: Gestão de Pessoas
A39: V COMPANY | B39: 2. Contas a Pagar | C39: Ações Endomarketing | D39: EMPRESA FUNERARIA NOSSA SENHORA DA CANDELARIA LTDA | E39: PIX - Referente a compra e envio de uma coroa de flores para o velório do pai da Nath. CHAVE : 21.567.458/0001-05 | F39: Fevereiro | G39: -450 | H39: -450 | I39: Ações Endomarketing | J39: Gestão de Pessoas
A40: V COMPANY | B40: 2. Contas a Pagar | C40: Ações Endomarketing | D40: FEAT PRODUCOES | E40: DIN - Ref a compra de 22 unidades de capivaras de pelúcia para a Lojinha da Viva | F40: Fevereiro | G40: -459.8 | H40: -459.8 | I40: Ações Endomarketing | J40: Gestão de Pessoas
A41: V COMPANY | B41: 2. Contas a Pagar | C41: Ações Endomarketing | D41: GUILHERME GONCALVES MELLO | E41: DIN REF A AÇÃO DO ROLETA ANIVERSARIO | F41: Fevereiro | G41: -50 | H41: -50 | I41: Ações Endomarketing | J41: Gestão de Pessoas
A42: V COMPANY | B42: 2. Contas a Pagar | C42: Ações Endomarketing | D42: GUILHERME GONCALVES MELLO | E42: PIX - ref a compra de isqueiro para utilizar nas ações aniversario do hub - Chave Pix: 24992683148 - Xp | F42: Fevereiro | G42: -6.98 | H42: -6.98 | I42: Ações Endomarketing | J42: Gestão de Pessoas
A43: V COMPANY | B43: 2. Contas a Pagar | C43: Ações Endomarketing | D43: LAURA CACADOR BRANCO | E43: DIN - REF A AÇÃO - ROLETA ANIVERSARIO | F43: Abril | G43: -50 | H43: -50 | I43: Ações Endomarketing | J43: Gestão de Pessoas
... A92: V EVENTOS BRASIL LTDA | B92: 2. Contas a Pagar | C92: Associações de classe | D92: ORDEM DOS ADVOGADOS DO BRASIL SECAO MINAS GERAIS | E92: REF A ANUIDADE 2026 - OAB VITOR PEDROSA SITE: https://www.oabmg.org.br/tesouraria/anuidade n° ordem: 107755 cpf 05253792660 pagar a vista | F92: Janeiro | G92: -1100 | H92: -1100 | I92: Associações de Classe | J92: Diretoria
A93: V EVENTOS BRASIL LTDA | B93: 2. Contas a Pagar | C93: Bens de pequeno valor | D93: C g center games ltda | E93: 23/01 MP*2PRODUTOS - COMPRA DE 1 CELULAR PARA PARA ADM | F93: Fevereiro | G93: -825 | H93: -825 | I93: CAPEX | J93: DESPESAS GERAIS | K93: CAPEX
A94: V EVENTOS BRASIL LTDA | B94: 2. Contas a Pagar | C94: Bens de pequeno valor | D94: J A Equipamentos | E94: Incluído a partir do recebimento da NF-e. BOL REF A COMPRA DE BATERIA PARA NOBREAKS | F94: Abril | G94: -534 | H94: -534 | I94: CAPEX | J94: DESPESAS GERAIS
A95: V EVENTOS BRASIL LTDA | B95: 2. Contas a Pagar | C95: Bens de pequeno valor | D95: J A Equipamentos | E95: Incluído a partir do recebimento da NF-e. BOL REF A COMPRA DE BATERIA PARA NOBREAKS | F95: Março | G95: -270 | H95: -270 | I95: CAPEX | J95: Administrativo
A96: V EVENTOS BRASIL LTDA | B96: 2. Contas a Pagar | C96: Bens de pequeno valor | D96: J A Equipamentos | E96: BOL REF A COMPRA DE BATERIA PARA NOBREAKS ** PAGAR PELO BB POR CAUSA DO DESCONTO DO BOLETO ** | F96: Março | G96: -130.02 | H96: -136 | I96: CAPEX | J96: Administrativo
A97: V EVENTOS BRASIL LTDA | B97: 2. Contas a Pagar | C97: Bens de pequeno valor | D97: MIANOFIX LTDA | E97: 19/01 MP*MAQUINHAMP - PASSADOR DE SLIDE | F97: Fevereiro | G97: -72.18 | H97: -72.18 | I97: CAPEX | J97: DESPESAS GERAIS | K97: CAPEX
A98: V EVENTOS BRASIL LTDA | B98: 2. Contas a Pagar | C98: Bens de pequeno valor | D98: PALACIO DAS FERRAMENTAS E PARAFUSOS LTDA | E98: 22/01 MP*2PRODUTOS - FURADEIRA HUB | F98: Fevereiro | G98: -497.9 | H98: -497.9 | I98: CAPEX | J98: DESPESAS GERAIS | K98: CAPEX
A99: V EVENTOS BRASIL LTDA | B99: 2. Contas a Pagar | C99: Bens de pequeno valor | D99: PHAETON | E99: Microfone Sem Fio Ulanzi - PARA O MKT | F99: Março | G99: -159.99 | H99: -159.99 | I99: CAPEX | J99: Administrativo
A100: V EVENTOS BRASIL LTDA | B100: 2. Contas a Pagar | C100: Bens de pequeno valor | D100: PHAETON | E100: 19/02 MP*2PRODUTOS - Microfone Ulanzi J12 2 Microfones Sem Fio - PARA O HUB | F100: Março | G100: -199.99 | H100: -199.99 | I100: CAPEX | J100: Administrativo
A101: V EVENTOS BRASIL LTDA | B101: 2. Contas a Pagar | C101: Bens de pequeno valor | D101: R7 SOLUCOES EM TECNOLOGIA LTDA | E101: Teclado E Mouse Sem Fio Dell - Para o Vitor | F101: Março | G101: -182.9 | H101: -182.9 | I101: CAPEX | J101: Administrativo
A102: V EVENTOS BRASIL LTDA | B102: 2. Contas a Pagar | C102: Bens de pequeno valor | D102: SET-SERVICOS TECNICOS EM INFORMATICA LTDA | E102: PIX - REF A COMPRA DE FOTE PC JESSICA CARVALHO | F102: Março | G102: -214.9 | H102: -214.9 | I102: CAPEX | J102: Administrativo
A103: V EVENTOS BRASIL LTDA | B103: 2. Contas a Pagar | C103: Bens de pequeno valor | D103: WS SMARTHOME | E103: 06/01 MP*MERCADOLIVRE - Ref a compra de 02 fontes para roteadores wifi | F103: Fevereiro | G103: -314 | H103: -314 | I103: CAPEX | J103: DESPESAS GERAIS | K103: CAPEX
A104: V EVENTOS BRASIL LTDA | B104: 2. Contas a Pagar | C104: Bens de pequeno valor (*) | D104: R10 COMERCIO E SERVICOS DE INFORMATICA LTDA | E104: 17/03 MP*MERCADOLIVRE -compra roteador TP LINK TL ER | F104: Abril | G104: -836.1 | H104: -836.1 | I104: CAPEX | J104: DESPESAS GERAIS
...

Sheet Página60
A1: Mês da Emissão | B1: Pago ou Recebido | C1: Setor | E1: SUM of Pago ou Recebido | F1: Mês da Emissão
A2: Julho | B2: 150 | C2: Diretoria | E2: Setor | F2: Julho | G2: Agosto | H2: Total Geral
A3: Julho | B3: 3385.05 | C3: Gestão de Pessoas | E3: Atendimento | F3: 2745.92 | G3: 4455.27 | H3: 7201.19 | I3: =G3 -> 4455.27 | J3: =F3 -> 2745.92
A4: Agosto | B4: 214.44 | C4: Financeiro Cash Out | E4: Consultoria e Performance | F4: 20817.19 | G4: 7245.32 | H4: 28062.51 | I4: =G4 -> 7245.32 | J4: =F4 -> 20817.19
A5: Agosto | B5: 117.95 | C5: FUNDO DE MARKETING | E5: DESPESAS GERAIS | F5: 9113.86 | G5: 11514.26 | H5: 20628.12 | I5: =G5 -> 11514.26 | J5: =F5 -> 9113.86
A6: Agosto | B6: 1845.2 | C6: Financeiro Cash Out | E6: Diretoria | F6: 13991.4 | G6: 22420.87 | H6: 36412.27 | I6: =G6 -> 22420.87 | J6: =F6 -> 13991.4 | L6: =I6+I5 -> 33935.13 | M6: =J6+J5 -> 23105.26
A7: Julho | B7: 38 | C7: Financeiro CSC | E7: EVENTOS OFICIAIS | F7: 17585.98 | H7: 17585.98 | I7: =G7 -> 0 | J7: =F7 -> 17585.98
A8: Julho | B8: 1485.2 | C8: Financeiro CSC | E8: Expansão | F8: 4732.11 | G8: 1757.02 | H8: 6489.13 | I8: =G8 -> 1757.02 | J8: =F8 -> 4732.11
A9: Julho | B9: 120 | C9: DESPESAS GERAIS | E9: Financeiro Cash Out | F9: 11.98 | G9: 3611.16 | H9: 3623.14 | I9: =G9 -> 3611.16 | J9: =F9 -> 11.98
A10: Julho | B10: -8344.22 | C10: Diretoria | E10: Financeiro CSC | F10: 13701.7 | G10: 14987.98 | H10: 28689.68 | I10: =G10 -> 14987.98 | J10: =F10 -> 13701.7
A11: Julho | B11: -6703.22 | C11: Diretoria | E11: FUNDO DE MARKETING | F11: 121.63 | G11: 723.56 | H11: 845.19 | I11: =G11 -> 723.56 | J11: =F11 -> 121.63
A12: Julho | B12: 60.49 | C12: Gestão de Pessoas | E12: Gestão | F12: 3484.17 | G12: 3673.93 | H12: 7158.1 | I12: =G12 -> 3673.93 | J12: =F12 -> 3484.17
A13: Julho | B13: -1738 | C13: Expansão | E13: Gestão de Pessoas | F13: 36887.95 | G13: 30632.46 | H13: 67520.41 | I13: =G13 -> 30632.46 | J13: =F13 -> 36887.95
A14: Julho | B14: 814.42 | C14: Financeiro CSC | E14: Marketing e Growth | F14: 8863.94 | G14: 14265.5 | H14: 23129.44 | I14: =G14 -> 14265.5 | J14: =F14 -> 8863.94
A15: Julho | B15: -0.01 | C15: Diretoria | E15: Pós-Vendas | F15: 5463.69 | G15: 2085.82 | H15: 7549.51 | I15: =G15 -> 2085.82 | J15: =F15 -> 5463.69
A16: Julho | B16: 93.1 | C16: Financeiro CSC | E16: TI | F16: 6613.34 | G16: 5066.16 | H16: 11679.5 | I16: =G16 -> 5066.16 | J16: =F16 -> 6613.34
A17: Julho | B17: 1.99 | C17: Financeiro CSC | E17: Total Geral | F17: 144134.86 | G17: 122439.31 | H17: 266574.17 | I17: =G17 -> 122439.31 | J17: =F17 -> 144134.86
A18: julho | B18: 427.34 | C18: Gestão de Pessoas
A19: Agosto | B19: 252.82 | C19: Gestão de Pessoas
A20: Julho | B20: 0.5 | C20: Financeiro CSC
A21: Julho | B21: 0.5 | C21: Financeiro CSC
A22: Julho | B22: 0.5 | C22: Financeiro CSC
A23: Julho | B23: 0.5 | C23: Financeiro CSC
A24: Julho | B24: 205.11 | C24: Gestão de Pessoas
A25: Julho | B25: 0.5 | C25: Financeiro CSC
A26: Julho | B26: 0.5 | C26: Financeiro CSC
A27: Julho | B27: 0.5 | C27: Financeiro CSC
A28: Julho | B28: 162.54 | C28: Gestão de Pessoas
A29: Julho | B29: 36.59 | C29: Gestão de Pessoas
... A708: Agosto | B708: 3500.39 | C708: Consultoria e Performance

Sheet Outras Informações
A2: RECEITAS
A4: Receitas inseridas manualmente | B4: janeiro | C4: fevereiro | D4: março | E4: abril | F4: maio | G4: junho | H4: julho | I4: agosto | J4: setembro | K4: outubro | L4: novembro | M4: dezembro | N4: TOTAL
A5: Royalties - Recorrentes | B5: =B32 -> 742596.16 | C5: =C32 -> 520688.71 | D5: =D32 -> 578703 | E5: =E32 -> 609147.54 | F5: =F32 -> 518335.49 | G5: =G32 -> 638364.5 | H5: =H32 -> 678311.33 | I5: =I32 -> 534530.06 | ... M5: =M32 -> 0 | N5: =SUM(B5:M5) -> 4820676.8
A6: Royalties - Fechamentos | B6: 115973.71 | C6: 77935.03 | D6: 28138.34 | E6: 23279.68 | F6: 12413.5 | G6: 111726.61 | H6: 87587.98 | I6: 71816.82 | N6: =SUM(B6:M6) -> 528871.67
A7: Fundo de Marketing - Recorrentes | B7: =B39 -> 46209.41 | C7: =C39 -> 30939.14 | D7: =D39 -> 38474.08 | E7: =E39 -> 35766.61 | F7: =F39 -> 32874.72 | G7: =G39 -> 44826.72 | H7: =H39 -> 43952.66 | I7: =I39 -> 36368.87 | ... M7: =M39 -> 0 | N7: =SUM(B7:M7) -> 309412.21
A8: Fundo de Marketing - Fechamentos | B8: 7285.45 | C8: 5088.37 | D8: 1796.06 | E8: 1497.89 | F8: 4076.76 | G8: 1291.73 | H8: 1291.73 | I8: 2333.17 | N8: =SUM(B8:M8) -> 24661.16
A9: Receita com Patrocínios | B9: 0 | C9: 0 | D9: 0 | E9: 0 | F9: 0 | G9: 0 | H9: 0 | I9: 0 | N9: =SUM(B9:M9) -> 0
A10: Receita SPDX | B10: =B22+B24 -> 435100.22 | C10: =C22+C24 -> 385150.49 | D10: =D22+D24 -> 538232.09 | E10: =E22+E24 -> 487174.31 | F10: =F22+F24 -> 486610.35 | G10: =G22+G24 -> 486259.18 | H10: =H22+H24 -> 517608.2 | I10: =I22+I24 -> 467285.15 | ... M10: =M22+M24 -> 0 | N10: =SUM(B10:M10) -> 3803420
A11: Receitas - Taxa Mundo Viva | B11: 76119.7 | C11: 73017 | D11: 71232.9 | E11: 70336.1 | F11: 73790.3 | G11: 73663 | H11: 76239.4 | I11: 77537.1 | N11: =SUM(B11:M11) -> 591935.5
A12: Markup de Liquidação de boletos | B12: =20493.31+13228.48 -> 33721.79 | C12: =18030.03+11473.79 -> 29503.82 | D12: =19882.64+17978.93 -> 37861.57 | E12: =15905.59+16071.59 -> 31977.18 | F12: =15840.02+16415.91 -> 32255.93 | G12: =17019.76+20571.26 -> 37591.02 | H12: =21429.4+18173.96 -> 39603.36 | I12: =15180.45+21515.92 -> 36696.37 | N12: =SUM(B12:M12) -> 279211.04
A13: Markup de cartão | B13: =137935.87+120.62 -> 138056.49 | C13: =72860.4+130.34 -> 72990.74 | D13: =72864.25+136.83 -> 73001.08 | E13: =73106.36+75.3 -> 73181.66 | F13: =109.41+90811.31 -> 90920.72 | G13: =89720.57+135.91 -> 89856.48 | H13: =116193.18+93.52 -> 116286.7 | I13: =69999.01+80.11 -> 70079.12 | N13: =SUM(B13:M13) -> 724372.99
A14: Markup de tarifas bancárias | B14: 3759.03 | C14: =2964.59 -> 2964.59 | D14: 4515 | E14: 2531.39 | F14: 2196.99 | G14: 2788.14 | H14: 3690.27 | I14: 3629.18 | N14: =SUM(B14:M14) -> 26074.59
